Workbook

Sheet Progress
A1: Contents of | C1: =SUM(C3:OFFSET(C3,10000,0)) -> 133763922099
A2: Progress.txt | B2: j_a | C2: Combinations Tried
A3: 03-07 12:18: j_a=1, 0 tried, 0 total, Squares: 0 G, 0 C, 0 F, 0 D, 0 GC, 0 FD, Triples: 0 GE, 0 CE, 0 GEC, 0 FE, 0 DE, 0 FED, 0 errs. | B3: =IF($A3="","",VALUE(MID($A3,(FIND("j_a=",$A3)+4),FIND(" ",$A3,FIND("j_a=",$A3))-(FIND("j_a=",$A3)+4)-1))) -> 1 | C3: =IF($A3="","",VALUE(TRIM(MID($A3,FIND(" ",$A3,FIND("j_a=",$A3)),FIND("tried",$A3)-FIND(" ",$A3,FIND("j_a=",$A3)))))) -> 0
A4: 03-07 12:18: j_a=2, 0 tried, 0 total, Squares: 0 G, 0 C, 0 F, 0 D, 0 GC, 0 FD, Triples: 0 GE, 0 CE, 0 GEC, 0 FE, 0 DE, 0 FED, 0 errs. | B4: =IF($A4="","",VALUE(MID($A4,(FIND("j_a=",$A4)+4),FIND(" ",$A4,FIND("j_a=",$A4))-(FIND("j_a=",$A4)+4)-1))) -> 2 | C4: =IF($A4="","",VALUE(TRIM(MID($A4,FIND(" ",$A4,FIND("j_a=",$A4)),FIND("tried",$A4)-FIND(" ",$A4,FIND("j_a=",$A4)))))) -> 0
A5: 03-07 12:18: j_a=3, 1 tried, 1 total, Squares: 0 G, 0 C, 0 F, 0 D, 0 GC, 0 FD, Triples: 0 GE, 0 CE, 0 GEC, 0 FE, 0 DE, 0 FED, 0 errs. | B5: =IF($A5="","",VALUE(MID($A5,(FIND("j_a=",$A5)+4),FIND(" ",$A5,FIND("j_a=",$A5))-(FIND("j_a=",$A5)+4)-1))) -> 3 | C5: =IF($A5="","",VALUE(TRIM(MID($A5,FIND(" ",$A5,FIND("j_a=",$A5)),FIND("tried",$A5)-FIND(" ",$A5,FIND("j_a=",$A5)))))) -> 1
A6: 03-07 12:18: j_a=4, 2 tried, 3 total, Squares: 0 G, 0 C, 0 F, 0 D, 0 GC, 0 FD, Triples: 0 GE, 0 CE, 0 GEC, 0 FE, 0 DE, 0 FED, 0 errs. | B6: =IF($A6="","",VALUE(MID($A6,(FIND("j_a=",$A6)+4),FIND(" ",$A6,FIND("j_a=",$A6))-(FIND("j_a=",$A6)+4)-1))) -> 4 | C6: =IF($A6="","",VALUE(TRIM(MID($A6,FIND(" ",$A6,FIND("j_a=",$A6)),FIND("tried",$A6)-FIND(" ",$A6,FIND("j_a=",$A6)))))) -> 2
A7: 03-07 12:18: j_a=5, 7 tried, 10 total, Squares: 0 G, 0 C, 0 F, 0 D, 0 GC, 0 FD, Triples: 0 GE, 0 CE, 0 GEC, 0 FE, 0 DE, 0 FED, 0 errs. | B7: =IF($A7="","",VALUE(MID($A7,(FIND("j_a=",$A7)+4),FIND(" ",$A7,FIND("j_a=",$A7))-(FIND("j_a=",$A7)+4)-1))) -> 5 | C7: =IF($A7="","",VALUE(TRIM(MID($A7,FIND(" ",$A7,FIND("j_a=",$A7)),FIND("tried",$A7)-FIND(" ",$A7,FIND("j_a=",$A7)))))) -> 7
A8: 03-07 12:18: j_a=6, 5 tried, 15 total, Squares: 0 G, 0 C, 0 F, 0 D, 0 GC, 0 FD, Triples: 0 GE, 0 CE, 0 GEC, 0 FE, 0 DE, 0 FED, 0 errs. | B8: =IF($A8="","",VALUE(MID($A8,(FIND("j_a=",$A8)+4),FIND(" ",$A8,FIND("j_a=",$A8))-(FIND("j_a=",$A8)+4)-1))) -> 6 | C8: =IF($A8="","",VALUE(TRIM(MID($A8,FIND(" ",$A8,FIND("j_a=",$A8)),FIND("tried",$A8)-FIND(" ",$A8,FIND("j_a=",$A8)))))) -> 5
A9: 03-07 12:18: j_a=7, 30 tried, 45 total, Squares: 0 G, 0 C, 0 F, 0 D, 0 GC, 0 FD, Triples: 0 GE, 0 CE, 0 GEC, 0 FE, 0 DE, 0 FED, 0 errs. | B9: =IF($A9="","",VALUE(MID($A9,(FIND("j_a=",$A9)+4),FIND(" ",$A9,FIND("j_a=",$A9))-(FIND("j_a=",$A9)+4)-1))) -> 7 | C9: =IF($A9="","",VALUE(TRIM(MID($A9,FIND(" ",$A9,FIND("j_a=",$A9)),FIND("tried",$A9)-FIND(" ",$A9,FIND("j_a=",$A9)))))) -> 30
A10: 03-07 12:18: j_a=8, 20 tried, 65 total, Squares: 0 G, 0 C, 0 F, 1 D, 0 GC, 0 FD, Triples: 0 GE, 0 CE, 0 GEC, 0 FE, 0 DE, 0 FED, 0 errs. | B10: =IF($A10="","",VALUE(MID($A10,(FIND("j_a=",$A10)+4),FIND(" ",$A10,FIND("j_a=",$A10))-(FIND("j_a=",$A10)+4)-1))) -> 8 | C10: =IF($A10="","",VALUE(TRIM(MID($A10,FIND(" ",$A10,FIND("j_a=",$A10)),FIND("tried",$A10)-FIND(" ",$A10,FIND("j_a=",$A10)))))) -> 20
A11: 03-07 12:18: j_a=9, 54 tried, 119 total, Squares: 0 G, 0 C, 0 F, 1 D, 0 GC, 0 FD, Triples: 0 GE, 0 CE, 0 GEC, 0 FE, 0 DE, 0 FED, 0 errs. | B11: =IF($A11="","",VALUE(MID($A11,(FIND("j_a=",$A11)+4),FIND(" ",$A11,FIND("j_a=",$A11))-(FIND("j_a=",$A11)+4)-1))) -> 9 | C11: =IF($A11="","",VALUE(TRIM(MID($A11,FIND(" ",$A11,FIND("j_a=",$A11)),FIND("tried",$A11)-FIND(" ",$A11,FIND("j_a=",$A11)))))) -> 54
A12: 03-07 12:18: j_a=10, 34 tried, 153 total, Squares: 0 G, 0 C, 0 F, 1 D, 0 GC, 0 FD, Triples: 0 GE, 0 CE, 0 GEC, 0 FE, 0 DE, 0 FED, 0 errs. | B12: =IF($A12="","",VALUE(MID($A12,(FIND("j_a=",$A12)+4),FIND(" ",$A12,FIND("j_a=",$A12))-(FIND("j_a=",$A12)+4)-1))) -> 10 | C12: =IF($A12="","",VALUE(TRIM(MID($A12,FIND(" ",$A12,FIND("j_a=",$A12)),FIND("tried",$A12)-FIND(" ",$A12,FIND("j_a=",$A12)))))) -> 34
A13: 03-07 12:18: j_a=11, 123 tried, 276 total, Squares: 0 G, 0 C, 0 F, 1 D, 0 GC, 0 FD, Triples: 0 GE, 0 CE, 0 GEC, 0 FE, 0 DE, 0 FED, 0 errs. | B13: =IF($A13="","",VALUE(MID($A13,(FIND("j_a=",$A13)+4),FIND(" ",$A13,FIND("j_a=",$A13))-(FIND("j_a=",$A13)+4)-1))) -> 11 | C13: =IF($A13="","",VALUE(TRIM(MID($A13,FIND(" ",$A13,FIND("j_a=",$A13)),FIND("tried",$A13)-FIND(" ",$A13,FIND("j_a=",$A13)))))) -> 123
A14: 03-07 12:18: j_a=12, 78 tried, 354 total, Squares: 0 G, 0 C, 0 F, 1 D, 0 GC, 0 FD, Triples: 0 GE, 0 CE, 0 GEC, 0 FE, 0 DE, 0 FED, 0 errs. | B14: =IF($A14="","",VALUE(MID($A14,(FIND("j_a=",$A14)+4),FIND(" ",$A14,FIND("j_a=",$A14))-(FIND("j_a=",$A14)+4)-1))) -> 12 | C14: =IF($A14="","",VALUE(TRIM(MID($A14,FIND(" ",$A14,FIND("j_a=",$A14)),FIND("tried",$A14)-FIND(" ",$A14,FIND("j_a=",$A14)))))) -> 78
... A1706: 03-09 07:14: j_a=1,704, 169,544,184 tried, 7,547,133,611 total, Squares: 4 G, 24 C, 2 F, 5 D, 0 GC, 0 FD, Triples: 0 GE, 0 CE, 0 GEC, 0 FE, 0 DE, 0 FED, 0 errs. | B1706: =IF($A1706="","",VALUE(MID($A1706,(FIND("j_a=",$A1706)+4),FIND(" ",$A1706,FIND("j_a=",$A1706))-(FIND("j_a=",$A1706)+4)-1))) -> 1704 | C1706: =IF($A1706="","",VALUE(TRIM(MID($A1706,FIND(" ",$A1706,FIND("j_a=",$A1706)),FIND("tried",$A1706)-FIND(" ",$A1706,FIND("j_a=",$A1706)))))) -> 169544184
B1707: =IF($A1707="","",VALUE(MID($A1707,(FIND("j_a=",$A1707)+4),FIND(" ",$A1707,FIND("j_a=",$A1707))-(FIND("j_a=",$A1707)+4)-1))) | C1707: =IF($A1707="","",VALUE(TRIM(MID($A1707,FIND(" ",$A1707,FIND("j_a=",$A1707)),FIND("tried",$A1707)-FIND(" ",$A1707,FIND("j_a=",$A1707))))))
B1708: =IF($A1708="","",VALUE(MID($A1708,(FIND("j_a=",$A1708)+4),FIND(" ",$A1708,FIND("j_a=",$A1708))-(FIND("j_a=",$A1708)+4)-1))) | C1708: =IF($A1708="","",VALUE(TRIM(MID($A1708,FIND(" ",$A1708,FIND("j_a=",$A1708)),FIND("tried",$A1708)-FIND(" ",$A1708,FIND("j_a=",$A1708))))))
B1709: =IF($A1709="","",VALUE(MID($A1709,(FIND("j_a=",$A1709)+4),FIND(" ",$A1709,FIND("j_a=",$A1709))-(FIND("j_a=",$A1709)+4)-1))) | C1709: =IF($A1709="","",VALUE(TRIM(MID($A1709,FIND(" ",$A1709,FIND("j_a=",$A1709)),FIND("tried",$A1709)-FIND(" ",$A1709,FIND("j_a=",$A1709))))))
B1710: =IF($A1710="","",VALUE(MID($A1710,(FIND("j_a=",$A1710)+4),FIND(" ",$A1710,FIND("j_a=",$A1710))-(FIND("j_a=",$A1710)+4)-1))) | C1710: =IF($A1710="","",VALUE(TRIM(MID($A1710,FIND(" ",$A1710,FIND("j_a=",$A1710)),FIND("tried",$A1710)-FIND(" ",$A1710,FIND("j_a=",$A1710))))))
B1711: =IF($A1711="","",VALUE(MID($A1711,(FIND("j_a=",$A1711)+4),FIND(" ",$A1711,FIND("j_a=",$A1711))-(FIND("j_a=",$A1711)+4)-1))) | C1711: =IF($A1711="","",VALUE(TRIM(MID($A1711,FIND(" ",$A1711,FIND("j_a=",$A1711)),FIND("tried",$A1711)-FIND(" ",$A1711,FIND("j_a=",$A1711))))))
B1712: =IF($A1712="","",VALUE(MID($A1712,(FIND("j_a=",$A1712)+4),FIND(" ",$A1712,FIND("j_a=",$A1712))-(FIND("j_a=",$A1712)+4)-1))) | C1712: =IF($A1712="","",VALUE(TRIM(MID($A1712,FIND(" ",$A1712,FIND("j_a=",$A1712)),FIND("tried",$A1712)-FIND(" ",$A1712,FIND("j_a=",$A1712))))))
B1713: =IF($A1713="","",VALUE(MID($A1713,(FIND("j_a=",$A1713)+4),FIND(" ",$A1713,FIND("j_a=",$A1713))-(FIND("j_a=",$A1713)+4)-1))) | C1713: =IF($A1713="","",VALUE(TRIM(MID($A1713,FIND(" ",$A1713,FIND("j_a=",$A1713)),FIND("tried",$A1713)-FIND(" ",$A1713,FIND("j_a=",$A1713))))))
B1714: =IF($A1714="","",VALUE(MID($A1714,(FIND("j_a=",$A1714)+4),FIND(" ",$A1714,FIND("j_a=",$A1714))-(FIND("j_a=",$A1714)+4)-1))) | C1714: =IF($A1714="","",VALUE(TRIM(MID($A1714,FIND(" ",$A1714,FIND("j_a=",$A1714)),FIND("tried",$A1714)-FIND(" ",$A1714,FIND("j_a=",$A1714))))))
B1715: =IF($A1715="","",VALUE(MID($A1715,(FIND("j_a=",$A1715)+4),FIND(" ",$A1715,FIND("j_a=",$A1715))-(FIND("j_a=",$A1715)+4)-1))) | C1715: =IF($A1715="","",VALUE(TRIM(MID($A1715,FIND(" ",$A1715,FIND("j_a=",$A1715)),FIND("tried",$A1715)-FIND(" ",$A1715,FIND("j_a=",$A1715))))))
B1716: =IF($A1716="","",VALUE(MID($A1716,(FIND("j_a=",$A1716)+4),FIND(" ",$A1716,FIND("j_a=",$A1716))-(FIND("j_a=",$A1716)+4)-1))) | C1716: =IF($A1716="","",VALUE(TRIM(MID($A1716,FIND(" ",$A1716,FIND("j_a=",$A1716)),FIND("tried",$A1716)-FIND(" ",$A1716,FIND("j_a=",$A1716))))))
B1717: =IF($A1717="","",VALUE(MID($A1717,(FIND("j_a=",$A1717)+4),FIND(" ",$A1717,FIND("j_a=",$A1717))-(FIND("j_a=",$A1717)+4)-1))) | C1717: =IF($A1717="","",VALUE(TRIM(MID($A1717,FIND(" ",$A1717,FIND("j_a=",$A1717)),FIND("tried",$A1717)-FIND(" ",$A1717,FIND("j_a=",$A1717))))))
B1718: =IF($A1718="","",VALUE(MID($A1718,(FIND("j_a=",$A1718)+4),FIND(" ",$A1718,FIND("j_a=",$A1718))-(FIND("j_a=",$A1718)+4)-1))) | C1718: =IF($A1718="","",VALUE(TRIM(MID($A1718,FIND(" ",$A1718,FIND("j_a=",$A1718)),FIND("tried",$A1718)-FIND(" ",$A1718,FIND("j_a=",$A1718))))))
... B4002: =IF($A4002="","",VALUE(MID($A4002,(FIND("j_a=",$A4002)+4),FIND(" ",$A4002,FIND("j_a=",$A4002))-(FIND("j_a=",$A4002)+4)-1))) | C4002: =IF($A4002="","",VALUE(TRIM(MID($A4002,FIND(" ",$A4002,FIND("j_a=",$A4002)),FIND("tried",$A4002)-FIND(" ",$A4002,FIND("j_a=",$A4002))))))

Sheet Results
A1: Contents of | B1: =COUNTIF(B3:OFFSET(B3,10000,0),"2 Sols")&" w/2 Solutions" -> 0 w/2 Solutions | D1: j_a= | E1: k_a= | F1: j_b= | G1: k_b= | H1: l_a= | I1: e_a= | J1: s_a= | K1: l_b= | L1: e_b= | M1: s_b= | N1: GCD | O1: 6th Sq | P1: Root | Q1: Final Square (roots) | R1: =TEXT(COUNTIF(S3:OFFSET(S3,10000,0),">0")+COUNTIF(T3:OFFSET(T3,10000,0),">0")++COUNTIF(V3:OFFSET(V3,10000,0),">0")++COUNTIF(W3:OFFSET(W3,10000,0),">0"), "#,##0")&" solutions for c,d,f,g" -> 2,215 solutions for c,d,f,g | S1: =TEXT(COUNTIF(S3:OFFSET(S3,10000,0),">0"),"#,##0")&" solutions for "&S2 -> 1,434 solutions for c | T1: =TEXT(COUNTIF(T3:OFFSET(T3,10000,0),">0"),"#,##0")&" solutions for "&T2 -> 364 solutions for d | V1: =TEXT(COUNTIF(V3:OFFSET(V3,10000,0),">0"),"#,##0")&" solutions for "&V2 -> 99 solutions for f | W1: =TEXT(COUNTIF(W3:OFFSET(W3,10000,0),">0"),"#,##0")&" solutions for "&W2 -> 318 solutions for g
A2: Results.txt | B2: =COUNTIF(B3:OFFSET(B3,10000,0),"Duplicate")&" Duplicate"&IF(COUNTIF(B3:OFFSET(B3,10000,0),"Duplicate")=1,"","s") -> 0 Duplicates | C2: Hash | G2: ] | L2: ] | O2: At | P2: Value | Q2: a | R2: b | S2: c | T2: d | U2: e | V2: f | W2: g | X2: h | Y2: i
A3: At [Seeds: j_a=8 k_a=7 j_b=7 k_b=6], [Entries: l_a=127 e_a=113 l_b=97 e_b=85], D=3,977^2. | B3: =IF(A3="","",IF(COUNTIF(C$2:C2,C3)>0,"Duplicate",IF(LEFT(C3,LEN(C3)-1)=LEFT(OFFSET(C3,-1,0),LEN(OFFSET(C3,-1,0))-1),"2 Sols",""))) | C3: =IF(A3="","",RIGHT("00000"&IF(OR($D3="",$E3="",$F3="",$G3=""),"",IF($D3>=$F3,$D3,$F3)),5)&"-" &RIGHT("00000"&IF(OR($D3="",$E3="",$F3="",$G3=""),"",IF($D3=$F3,IF($E3>=$G3,$E3,$G3),IF($D3>$F3,$E3,$G3))),5)&"-" &RIGHT("00000"&IF(OR($D3="",$E3="",$F3="",$G3=""),"",IF($D3<$F3,$D3,$F3)),5)&"-" &RIGHT("00000"&IF(OR($D3="",$E3="",$F3="",$G3=""),"",IF($D3=$F3,IF($E3<$G3,$E3,$G3),IF($D3<$F3,$E3,$G3))),5)&"-"&O3) -> 00008-00007-00007-00006-D | D3: =IF($A3="","",VALUE(MID($A3,FIND(D$1,$A3)+LEN(D$1),FIND(D$2,$A3,FIND(D$1,$A3))-(FIND(D$1,$A3)+LEN(D$1))))) -> 8 | E3: =IF($A3="","",VALUE(MID($A3,FIND(E$1,$A3)+LEN(E$1),FIND(E$2,$A3,FIND(E$1,$A3))-(FIND(E$1,$A3)+LEN(E$1))))) -> 7 | F3: =IF($A3="","",VALUE(MID($A3,FIND(F$1,$A3)+LEN(F$1),FIND(F$2,$A3,FIND(F$1,$A3))-(FIND(F$1,$A3)+LEN(F$1))))) -> 7 | G3: =IF($A3="","",VALUE(MID($A3,FIND(G$1,$A3)+LEN(G$1),FIND(G$2,$A3,FIND(G$1,$A3))-(FIND(G$1,$A3)+LEN(G$1))))) -> 6 | H3: =IF($A3="","",VALUE(MID($A3,FIND(H$1,$A3)+LEN(H$1),FIND(H$2,$A3,FIND(H$1,$A3))-(FIND(H$1,$A3)+LEN(H$1))))) -> 127 | I3: =IF($A3="","",VALUE(MID($A3,FIND(I$1,$A3)+LEN(I$1),FIND(I$2,$A3,FIND(I$1,$A3))-(FIND(I$1,$A3)+LEN(I$1))))) -> 113 | J3: =IF(OR($D3="",$E3=""),"",$E3^2+2*$E3*$D3-$D3^2) -> 97 | K3: =IF($A3="","",VALUE(MID($A3,FIND(K$1,$A3)+LEN(K$1),FIND(K$2,$A3,FIND(K$1,$A3))-(FIND(K$1,$A3)+LEN(K$1))))) -> 97 | L3: =IF($A3="","",VALUE(MID($A3,FIND(L$1,$A3)+LEN(L$1),FIND(L$2,$A3,FIND(L$1,$A3))-(FIND(L$1,$A3)+LEN(L$1))))) -> 85 | M3: =IF(OR($F3="",$G3=""),"",$G3^2+2*$G3*$F3-$F3^2) -> 71 | N3: =IF(OR($H3="",$I3="",$J3="",$K3="",$L3="",$M3=""),"",GCD($H3:$M3)) -> 1 | O3: =IF($A3="","",MID($A3,FIND(" ",$A3,FIND(L$1,$A3))+1,1)) -> D | P3: =IF(A3="","",TRIM(SUBSTITUTE(SUBSTITUTE(RIGHT(A3,LEN(A3)-FIND("=",A3,FIND("]",A3,FIND("]",A3)+1))),"^2",""),".",""))) -> 3,977 | Q3: =IF(OR($H3="",$L3="",$N3=""),"",$H3*$L3/$N3) -> 10795 | R3: =IF(OR($K3="",$I3="",$N3=""),"",$K3*$I3/$N3) -> 10961 | S3: =IF(OR($O3<>UPPER(S$2),$N3=""),"",IF($P3="",-1,$P3/$N3)) | T3: =IF(OR($O3<>UPPER(T$2),$N3=""),"",IF($P3="",-1,$P3/$N3)) -> 3977 | U3: =IF(OR($I3="",$L3="",$N3=""),"",$I3*$L3/$N3) -> 9605 | V3: =IF(OR($O3<>UPPER(V$2),$N3=""),"",IF($P3="",-1,$P3/$N3)) | W3: =IF(OR($O3<>UPPER(W$2),$N3=""),"",IF($P3="",-1,$P3/$N3)) | X3: =IF(OR($M3="",$I3="",$N3=""),"",$M3*$I3/$N3) -> 8023 | Y3: =IF(OR($J3="",$L3="",$N3=""),"",$J3*$L3/$N3) -> 8245
A4: At [Seeds: j_a=13 k_a=11 j_b=9 k_b=8], [Entries: l_a=334 e_a=290 l_b=161 e_b=145], D=14,210^2. | B4: =IF(A4="","",IF(COUNTIF(C$2:C3,C4)>0,"Duplicate",IF(LEFT(C4,LEN(C4)-1)=LEFT(OFFSET(C4,-1,0),LEN(OFFSET(C4,-1,0))-1),"2 Sols",""))) | C4: =IF(A4="","",RIGHT("00000"&IF(OR($D4="",$E4="",$F4="",$G4=""),"",IF($D4>=$F4,$D4,$F4)),5)&"-" &RIGHT("00000"&IF(OR($D4="",$E4="",$F4="",$G4=""),"",IF($D4=$F4,IF($E4>=$G4,$E4,$G4),IF($D4>$F4,$E4,$G4))),5)&"-" &RIGHT("00000"&IF(OR($D4="",$E4="",$F4="",$G4=""),"",IF($D4<$F4,$D4,$F4)),5)&"-" &RIGHT("00000"&IF(OR($D4="",$E4="",$F4="",$G4=""),"",IF($D4=$F4,IF($E4<$G4,$E4,$G4),IF($D4<$F4,$E4,$G4))),5)&"-"&O4) -> 00013-00011-00009-00008-D | D4: =IF($A4="","",VALUE(MID($A4,FIND(D$1,$A4)+LEN(D$1),FIND(D$2,$A4,FIND(D$1,$A4))-(FIND(D$1,$A4)+LEN(D$1))))) -> 13 | E4: =IF($A4="","",VALUE(MID($A4,FIND(E$1,$A4)+LEN(E$1),FIND(E$2,$A4,FIND(E$1,$A4))-(FIND(E$1,$A4)+LEN(E$1))))) -> 11 | F4: =IF($A4="","",VALUE(MID($A4,FIND(F$1,$A4)+LEN(F$1),FIND(F$2,$A4,FIND(F$1,$A4))-(FIND(F$1,$A4)+LEN(F$1))))) -> 9 | G4: =IF($A4="","",VALUE(MID($A4,FIND(G$1,$A4)+LEN(G$1),FIND(G$2,$A4,FIND(G$1,$A4))-(FIND(G$1,$A4)+LEN(G$1))))) -> 8 | H4: =IF($A4="","",VALUE(MID($A4,FIND(H$1,$A4)+LEN(H$1),FIND(H$2,$A4,FIND(H$1,$A4))-(FIND(H$1,$A4)+LEN(H$1))))) -> 334 | I4: =IF($A4="","",VALUE(MID($A4,FIND(I$1,$A4)+LEN(I$1),FIND(I$2,$A4,FIND(I$1,$A4))-(FIND(I$1,$A4)+LEN(I$1))))) -> 290 | J4: =IF(OR($D4="",$E4=""),"",$E4^2+2*$E4*$D4-$D4^2) -> 238 | K4: =IF($A4="","",VALUE(MID($A4,FIND(K$1,$A4)+LEN(K$1),FIND(K$2,$A4,FIND(K$1,$A4))-(FIND(K$1,$A4)+LEN(K$1))))) -> 161 | L4: =IF($A4="","",VALUE(MID($A4,FIND(L$1,$A4)+LEN(L$1),FIND(L$2,$A4,FIND(L$1,$A4))-(FIND(L$1,$A4)+LEN(L$1))))) -> 145 | M4: =IF(OR($F4="",$G4=""),"",$G4^2+2*$G4*$F4-$F4^2) -> 127 | N4: =IF(OR($H4="",$I4="",$J4="",$K4="",$L4="",$M4=""),"",GCD($H4:$M4)) -> 1 | O4: =IF($A4="","",MID($A4,FIND(" ",$A4,FIND(L$1,$A4))+1,1)) -> D | P4: =IF(A4="","",TRIM(SUBSTITUTE(SUBSTITUTE(RIGHT(A4,LEN(A4)-FIND("=",A4,FIND("]",A4,FIND("]",A4)+1))),"^2",""),".",""))) -> 14,210 | Q4: =IF(OR($H4="",$L4="",$N4=""),"",$H4*$L4/$N4) -> 48430 | R4: =IF(OR($K4="",$I4="",$N4=""),"",$K4*$I4/$N4) -> 46690 | S4: =IF(OR($O4<>UPPER(S$2),$N4=""),"",IF($P4="",-1,$P4/$N4)) | T4: =IF(OR($O4<>UPPER(T$2),$N4=""),"",IF($P4="",-1,$P4/$N4)) -> 14210 | U4: =IF(OR($I4="",$L4="",$N4=""),"",$I4*$L4/$N4) -> 42050 | V4: =IF(OR($O4<>UPPER(V$2),$N4=""),"",IF($P4="",-1,$P4/$N4)) | W4: =IF(OR($O4<>UPPER(W$2),$N4=""),"",IF($P4="",-1,$P4/$N4)) | X4: =IF(OR($M4="",$I4="",$N4=""),"",$M4*$I4/$N4) -> 36830 | Y4: =IF(OR($J4="",$L4="",$N4=""),"",$J4*$L4/$N4) -> 34510
A5: At [Seeds: j_a=16 k_a=13 j_b=15 k_b=11], [Entries: l_a=503 e_a=425 l_b=434 e_b=346], C=23,666^2. | B5: =IF(A5="","",IF(COUNTIF(C$2:C4,C5)>0,"Duplicate",IF(LEFT(C5,LEN(C5)-1)=LEFT(OFFSET(C5,-1,0),LEN(OFFSET(C5,-1,0))-1),"2 Sols",""))) | C5: =IF(A5="","",RIGHT("00000"&IF(OR($D5="",$E5="",$F5="",$G5=""),"",IF($D5>=$F5,$D5,$F5)),5)&"-" &RIGHT("00000"&IF(OR($D5="",$E5="",$F5="",$G5=""),"",IF($D5=$F5,IF($E5>=$G5,$E5,$G5),IF($D5>$F5,$E5,$G5))),5)&"-" &RIGHT("00000"&IF(OR($D5="",$E5="",$F5="",$G5=""),"",IF($D5<$F5,$D5,$F5)),5)&"-" &RIGHT("00000"&IF(OR($D5="",$E5="",$F5="",$G5=""),"",IF($D5=$F5,IF($E5<$G5,$E5,$G5),IF($D5<$F5,$E5,$G5))),5)&"-"&O5) -> 00016-00013-00015-00011-C | D5: =IF($A5="","",VALUE(MID($A5,FIND(D$1,$A5)+LEN(D$1),FIND(D$2,$A5,FIND(D$1,$A5))-(FIND(D$1,$A5)+LEN(D$1))))) -> 16 | E5: =IF($A5="","",VALUE(MID($A5,FIND(E$1,$A5)+LEN(E$1),FIND(E$2,$A5,FIND(E$1,$A5))-(FIND(E$1,$A5)+LEN(E$1))))) -> 13 | F5: =IF($A5="","",VALUE(MID($A5,FIND(F$1,$A5)+LEN(F$1),FIND(F$2,$A5,FIND(F$1,$A5))-(FIND(F$1,$A5)+LEN(F$1))))) -> 15 | G5: =IF($A5="","",VALUE(MID($A5,FIND(G$1,$A5)+LEN(G$1),FIND(G$2,$A5,FIND(G$1,$A5))-(FIND(G$1,$A5)+LEN(G$1))))) -> 11 | H5: =IF($A5="","",VALUE(MID($A5,FIND(H$1,$A5)+LEN(H$1),FIND(H$2,$A5,FIND(H$1,$A5))-(FIND(H$1,$A5)+LEN(H$1))))) -> 503 | I5: =IF($A5="","",VALUE(MID($A5,FIND(I$1,$A5)+LEN(I$1),FIND(I$2,$A5,FIND(I$1,$A5))-(FIND(I$1,$A5)+LEN(I$1))))) -> 425 | J5: =IF(OR($D5="",$E5=""),"",$E5^2+2*$E5*$D5-$D5^2) -> 329 | K5: =IF($A5="","",VALUE(MID($A5,FIND(K$1,$A5)+LEN(K$1),FIND(K$2,$A5,FIND(K$1,$A5))-(FIND(K$1,$A5)+LEN(K$1))))) -> 434 | L5: =IF($A5="","",VALUE(MID($A5,FIND(L$1,$A5)+LEN(L$1),FIND(L$2,$A5,FIND(L$1,$A5))-(FIND(L$1,$A5)+LEN(L$1))))) -> 346 | M5: =IF(OR($F5="",$G5=""),"",$G5^2+2*$G5*$F5-$F5^2) -> 226 | N5: =IF(OR($H5="",$I5="",$J5="",$K5="",$L5="",$M5=""),"",GCD($H5:$M5)) -> 1 | O5: =IF($A5="","",MID($A5,FIND(" ",$A5,FIND(L$1,$A5))+1,1)) -> C | P5: =IF(A5="","",TRIM(SUBSTITUTE(SUBSTITUTE(RIGHT(A5,LEN(A5)-FIND("=",A5,FIND("]",A5,FIND("]",A5)+1))),"^2",""),".",""))) -> 23,666 | Q5: =IF(OR($H5="",$L5="",$N5=""),"",$H5*$L5/$N5) -> 174038 | R5: =IF(OR($K5="",$I5="",$N5=""),"",$K5*$I5/$N5) -> 184450 | S5: =IF(OR($O5<>UPPER(S$2),$N5=""),"",IF($P5="",-1,$P5/$N5)) -> 23666 | T5: =IF(OR($O5<>UPPER(T$2),$N5=""),"",IF($P5="",-1,$P5/$N5)) | U5: =IF(OR($I5="",$L5="",$N5=""),"",$I5*$L5/$N5) -> 147050 | V5: =IF(OR($O5<>UPPER(V$2),$N5=""),"",IF($P5="",-1,$P5/$N5)) | W5: =IF(OR($O5<>UPPER(W$2),$N5=""),"",IF($P5="",-1,$P5/$N5)) | X5: =IF(OR($M5="",$I5="",$N5=""),"",$M5*$I5/$N5) -> 96050 | Y5: =IF(OR($J5="",$L5="",$N5=""),"",$J5*$L5/$N5) -> 113834
A6: At [Seeds: j_a=21 k_a=16 j_b=9 k_b=7], [Entries: l_a=857 e_a=697 l_b=158 e_b=130], C=9,518^2. | B6: =IF(A6="","",IF(COUNTIF(C$2:C5,C6)>0,"Duplicate",IF(LEFT(C6,LEN(C6)-1)=LEFT(OFFSET(C6,-1,0),LEN(OFFSET(C6,-1,0))-1),"2 Sols",""))) | C6: =IF(A6="","",RIGHT("00000"&IF(OR($D6="",$E6="",$F6="",$G6=""),"",IF($D6>=$F6,$D6,$F6)),5)&"-" &RIGHT("00000"&IF(OR($D6="",$E6="",$F6="",$G6=""),"",IF($D6=$F6,IF($E6>=$G6,$E6,$G6),IF($D6>$F6,$E6,$G6))),5)&"-" &RIGHT("00000"&IF(OR($D6="",$E6="",$F6="",$G6=""),"",IF($D6<$F6,$D6,$F6)),5)&"-" &RIGHT("00000"&IF(OR($D6="",$E6="",$F6="",$G6=""),"",IF($D6=$F6,IF($E6<$G6,$E6,$G6),IF($D6<$F6,$E6,$G6))),5)&"-"&O6) -> 00021-00016-00009-00007-C | D6: =IF($A6="","",VALUE(MID($A6,FIND(D$1,$A6)+LEN(D$1),FIND(D$2,$A6,FIND(D$1,$A6))-(FIND(D$1,$A6)+LEN(D$1))))) -> 21 | E6: =IF($A6="","",VALUE(MID($A6,FIND(E$1,$A6)+LEN(E$1),FIND(E$2,$A6,FIND(E$1,$A6))-(FIND(E$1,$A6)+LEN(E$1))))) -> 16 | F6: =IF($A6="","",VALUE(MID($A6,FIND(F$1,$A6)+LEN(F$1),FIND(F$2,$A6,FIND(F$1,$A6))-(FIND(F$1,$A6)+LEN(F$1))))) -> 9 | G6: =IF($A6="","",VALUE(MID($A6,FIND(G$1,$A6)+LEN(G$1),FIND(G$2,$A6,FIND(G$1,$A6))-(FIND(G$1,$A6)+LEN(G$1))))) -> 7 | H6: =IF($A6="","",VALUE(MID($A6,FIND(H$1,$A6)+LEN(H$1),FIND(H$2,$A6,FIND(H$1,$A6))-(FIND(H$1,$A6)+LEN(H$1))))) -> 857 | I6: =IF($A6="","",VALUE(MID($A6,FIND(I$1,$A6)+LEN(I$1),FIND(I$2,$A6,FIND(I$1,$A6))-(FIND(I$1,$A6)+LEN(I$1))))) -> 697 | J6: =IF(OR($D6="",$E6=""),"",$E6^2+2*$E6*$D6-$D6^2) -> 487 | K6: =IF($A6="","",VALUE(MID($A6,FIND(K$1,$A6)+LEN(K$1),FIND(K$2,$A6,FIND(K$1,$A6))-(FIND(K$1,$A6)+LEN(K$1))))) -> 158 | L6: =IF($A6="","",VALUE(MID($A6,FIND(L$1,$A6)+LEN(L$1),FIND(L$2,$A6,FIND(L$1,$A6))-(FIND(L$1,$A6)+LEN(L$1))))) -> 130 | M6: =IF(OR($F6="",$G6=""),"",$G6^2+2*$G6*$F6-$F6^2) -> 94 | N6: =IF(OR($H6="",$I6="",$J6="",$K6="",$L6="",$M6=""),"",GCD($H6:$M6)) -> 1 | O6: =IF($A6="","",MID($A6,FIND(" ",$A6,FIND(L$1,$A6))+1,1)) -> C | P6: =IF(A6="","",TRIM(SUBSTITUTE(SUBSTITUTE(RIGHT(A6,LEN(A6)-FIND("=",A6,FIND("]",A6,FIND("]",A6)+1))),"^2",""),".",""))) -> 9,518 | Q6: =IF(OR($H6="",$L6="",$N6=""),"",$H6*$L6/$N6) -> 111410 | R6: =IF(OR($K6="",$I6="",$N6=""),"",$K6*$I6/$N6) -> 110126 | S6: =IF(OR($O6<>UPPER(S$2),$N6=""),"",IF($P6="",-1,$P6/$N6)) -> 9518 | T6: =IF(OR($O6<>UPPER(T$2),$N6=""),"",IF($P6="",-1,$P6/$N6)) | U6: =IF(OR($I6="",$L6="",$N6=""),"",$I6*$L6/$N6) -> 90610 | V6: =IF(OR($O6<>UPPER(V$2),$N6=""),"",IF($P6="",-1,$P6/$N6)) | W6: =IF(OR($O6<>UPPER(W$2),$N6=""),"",IF($P6="",-1,$P6/$N6)) | X6: =IF(OR($M6="",$I6="",$N6=""),"",$M6*$I6/$N6) -> 65518 | Y6: =IF(OR($J6="",$L6="",$N6=""),"",$J6*$L6/$N6) -> 63310
A7: At [Seeds: j_a=21 k_a=17 j_b=14 k_b=13], [Entries: l_a=866 e_a=730 l_b=391 e_b=365], D=51,830^2. | B7: =IF(A7="","",IF(COUNTIF(C$2:C6,C7)>0,"Duplicate",IF(LEFT(C7,LEN(C7)-1)=LEFT(OFFSET(C7,-1,0),LEN(OFFSET(C7,-1,0))-1),"2 Sols",""))) | C7: =IF(A7="","",RIGHT("00000"&IF(OR($D7="",$E7="",$F7="",$G7=""),"",IF($D7>=$F7,$D7,$F7)),5)&"-" &RIGHT("00000"&IF(OR($D7="",$E7="",$F7="",$G7=""),"",IF($D7=$F7,IF($E7>=$G7,$E7,$G7),IF($D7>$F7,$E7,$G7))),5)&"-" &RIGHT("00000"&IF(OR($D7="",$E7="",$F7="",$G7=""),"",IF($D7<$F7,$D7,$F7)),5)&"-" &RIGHT("00000"&IF(OR($D7="",$E7="",$F7="",$G7=""),"",IF($D7=$F7,IF($E7<$G7,$E7,$G7),IF($D7<$F7,$E7,$G7))),5)&"-"&O7) -> 00021-00017-00014-00013-D | D7: =IF($A7="","",VALUE(MID($A7,FIND(D$1,$A7)+LEN(D$1),FIND(D$2,$A7,FIND(D$1,$A7))-(FIND(D$1,$A7)+LEN(D$1))))) -> 21 | E7: =IF($A7="","",VALUE(MID($A7,FIND(E$1,$A7)+LEN(E$1),FIND(E$2,$A7,FIND(E$1,$A7))-(FIND(E$1,$A7)+LEN(E$1))))) -> 17 | F7: =IF($A7="","",VALUE(MID($A7,FIND(F$1,$A7)+LEN(F$1),FIND(F$2,$A7,FIND(F$1,$A7))-(FIND(F$1,$A7)+LEN(F$1))))) -> 14 | G7: =IF($A7="","",VALUE(MID($A7,FIND(G$1,$A7)+LEN(G$1),FIND(G$2,$A7,FIND(G$1,$A7))-(FIND(G$1,$A7)+LEN(G$1))))) -> 13 | H7: =IF($A7="","",VALUE(MID($A7,FIND(H$1,$A7)+LEN(H$1),FIND(H$2,$A7,FIND(H$1,$A7))-(FIND(H$1,$A7)+LEN(H$1))))) -> 866 | I7: =IF($A7="","",VALUE(MID($A7,FIND(I$1,$A7)+LEN(I$1),FIND(I$2,$A7,FIND(I$1,$A7))-(FIND(I$1,$A7)+LEN(I$1))))) -> 730 | J7: =IF(OR($D7="",$E7=""),"",$E7^2+2*$E7*$D7-$D7^2) -> 562 | K7: =IF($A7="","",VALUE(MID($A7,FIND(K$1,$A7)+LEN(K$1),FIND(K$2,$A7,FIND(K$1,$A7))-(FIND(K$1,$A7)+LEN(K$1))))) -> 391 | L7: =IF($A7="","",VALUE(MID($A7,FIND(L$1,$A7)+LEN(L$1),FIND(L$2,$A7,FIND(L$1,$A7))-(FIND(L$1,$A7)+LEN(L$1))))) -> 365 | M7: =IF(OR($F7="",$G7=""),"",$G7^2+2*$G7*$F7-$F7^2) -> 337 | N7: =IF(OR($H7="",$I7="",$J7="",$K7="",$L7="",$M7=""),"",GCD($H7:$M7)) -> 1 | O7: =IF($A7="","",MID($A7,FIND(" ",$A7,FIND(L$1,$A7))+1,1)) -> D | P7: =IF(A7="","",TRIM(SUBSTITUTE(SUBSTITUTE(RIGHT(A7,LEN(A7)-FIND("=",A7,FIND("]",A7,FIND("]",A7)+1))),"^2",""),".",""))) -> 51,830 | Q7: =IF(OR($H7="",$L7="",$N7=""),"",$H7*$L7/$N7) -> 316090 | R7: =IF(OR($K7="",$I7="",$N7=""),"",$K7*$I7/$N7) -> 285430 | S7: =IF(OR($O7<>UPPER(S$2),$N7=""),"",IF($P7="",-1,$P7/$N7)) | T7: =IF(OR($O7<>UPPER(T$2),$N7=""),"",IF($P7="",-1,$P7/$N7)) -> 51830 | U7: =IF(OR($I7="",$L7="",$N7=""),"",$I7*$L7/$N7) -> 266450 | V7: =IF(OR($O7<>UPPER(V$2),$N7=""),"",IF($P7="",-1,$P7/$N7)) | W7: =IF(OR($O7<>UPPER(W$2),$N7=""),"",IF($P7="",-1,$P7/$N7)) | X7: =IF(OR($M7="",$I7="",$N7=""),"",$M7*$I7/$N7) -> 246010 | Y7: =IF(OR($J7="",$L7="",$N7=""),"",$J7*$L7/$N7) -> 205130
A8: At [Seeds: j_a=22 k_a=19 j_b=3 k_b=2], [Entries: l_a=959 e_a=845 l_b=17 e_b=13], C=481^2. | B8: =IF(A8="","",IF(COUNTIF(C$2:C7,C8)>0,"Duplicate",IF(LEFT(C8,LEN(C8)-1)=LEFT(OFFSET(C8,-1,0),LEN(OFFSET(C8,-1,0))-1),"2 Sols",""))) | C8: =IF(A8="","",RIGHT("00000"&IF(OR($D8="",$E8="",$F8="",$G8=""),"",IF($D8>=$F8,$D8,$F8)),5)&"-" &RIGHT("00000"&IF(OR($D8="",$E8="",$F8="",$G8=""),"",IF($D8=$F8,IF($E8>=$G8,$E8,$G8),IF($D8>$F8,$E8,$G8))),5)&"-" &RIGHT("00000"&IF(OR($D8="",$E8="",$F8="",$G8=""),"",IF($D8<$F8,$D8,$F8)),5)&"-" &RIGHT("00000"&IF(OR($D8="",$E8="",$F8="",$G8=""),"",IF($D8=$F8,IF($E8<$G8,$E8,$G8),IF($D8<$F8,$E8,$G8))),5)&"-"&O8) -> 00022-00019-00003-00002-C | D8: =IF($A8="","",VALUE(MID($A8,FIND(D$1,$A8)+LEN(D$1),FIND(D$2,$A8,FIND(D$1,$A8))-(FIND(D$1,$A8)+LEN(D$1))))) -> 22 | E8: =IF($A8="","",VALUE(MID($A8,FIND(E$1,$A8)+LEN(E$1),FIND(E$2,$A8,FIND(E$1,$A8))-(FIND(E$1,$A8)+LEN(E$1))))) -> 19 | F8: =IF($A8="","",VALUE(MID($A8,FIND(F$1,$A8)+LEN(F$1),FIND(F$2,$A8,FIND(F$1,$A8))-(FIND(F$1,$A8)+LEN(F$1))))) -> 3 | G8: =IF($A8="","",VALUE(MID($A8,FIND(G$1,$A8)+LEN(G$1),FIND(G$2,$A8,FIND(G$1,$A8))-(FIND(G$1,$A8)+LEN(G$1))))) -> 2 | H8: =IF($A8="","",VALUE(MID($A8,FIND(H$1,$A8)+LEN(H$1),FIND(H$2,$A8,FIND(H$1,$A8))-(FIND(H$1,$A8)+LEN(H$1))))) -> 959 | I8: =IF($A8="","",VALUE(MID($A8,FIND(I$1,$A8)+LEN(I$1),FIND(I$2,$A8,FIND(I$1,$A8))-(FIND(I$1,$A8)+LEN(I$1))))) -> 845 | J8: =IF(OR($D8="",$E8=""),"",$E8^2+2*$E8*$D8-$D8^2) -> 713 | K8: =IF($A8="","",VALUE(MID($A8,FIND(K$1,$A8)+LEN(K$1),FIND(K$2,$A8,FIND(K$1,$A8))-(FIND(K$1,$A8)+LEN(K$1))))) -> 17 | L8: =IF($A8="","",VALUE(MID($A8,FIND(L$1,$A8)+LEN(L$1),FIND(L$2,$A8,FIND(L$1,$A8))-(FIND(L$1,$A8)+LEN(L$1))))) -> 13 | M8: =IF(OR($F8="",$G8=""),"",$G8^2+2*$G8*$F8-$F8^2) -> 7 | N8: =IF(OR($H8="",$I8="",$J8="",$K8="",$L8="",$M8=""),"",GCD($H8:$M8)) -> 1 | O8: =IF($A8="","",MID($A8,FIND(" ",$A8,FIND(L$1,$A8))+1,1)) -> C | P8: =IF(A8="","",TRIM(SUBSTITUTE(SUBSTITUTE(RIGHT(A8,LEN(A8)-FIND("=",A8,FIND("]",A8,FIND("]",A8)+1))),"^2",""),".",""))) -> 481 | Q8: =IF(OR($H8="",$L8="",$N8=""),"",$H8*$L8/$N8) -> 12467 | R8: =IF(OR($K8="",$I8="",$N8=""),"",$K8*$I8/$N8) -> 14365 | S8: =IF(OR($O8<>UPPER(S$2),$N8=""),"",IF($P8="",-1,$P8/$N8)) -> 481 | T8: =IF(OR($O8<>UPPER(T$2),$N8=""),"",IF($P8="",-1,$P8/$N8)) | U8: =IF(OR($I8="",$L8="",$N8=""),"",$I8*$L8/$N8) -> 10985 | V8: =IF(OR($O8<>UPPER(V$2),$N8=""),"",IF($P8="",-1,$P8/$N8)) | W8: =IF(OR($O8<>UPPER(W$2),$N8=""),"",IF($P8="",-1,$P8/$N8)) | X8: =IF(OR($M8="",$I8="",$N8=""),"",$M8*$I8/$N8) -> 5915 | Y8: =IF(OR($J8="",$L8="",$N8=""),"",$J8*$L8/$N8) -> 9269
A9: At [Seeds: j_a=29 k_a=23 j_b=19 k_b=18], [Entries: l_a=1,646 e_a=1,370 l_b=721 e_b=685], D=67,130^2. | B9: =IF(A9="","",IF(COUNTIF(C$2:C8,C9)>0,"Duplicate",IF(LEFT(C9,LEN(C9)-1)=LEFT(OFFSET(C9,-1,0),LEN(OFFSET(C9,-1,0))-1),"2 Sols",""))) | C9: =IF(A9="","",RIGHT("00000"&IF(OR($D9="",$E9="",$F9="",$G9=""),"",IF($D9>=$F9,$D9,$F9)),5)&"-" &RIGHT("00000"&IF(OR($D9="",$E9="",$F9="",$G9=""),"",IF($D9=$F9,IF($E9>=$G9,$E9,$G9),IF($D9>$F9,$E9,$G9))),5)&"-" &RIGHT("00000"&IF(OR($D9="",$E9="",$F9="",$G9=""),"",IF($D9<$F9,$D9,$F9)),5)&"-" &RIGHT("00000"&IF(OR($D9="",$E9="",$F9="",$G9=""),"",IF($D9=$F9,IF($E9<$G9,$E9,$G9),IF($D9<$F9,$E9,$G9))),5)&"-"&O9) -> 00029-00023-00019-00018-D | D9: =IF($A9="","",VALUE(MID($A9,FIND(D$1,$A9)+LEN(D$1),FIND(D$2,$A9,FIND(D$1,$A9))-(FIND(D$1,$A9)+LEN(D$1))))) -> 29 | E9: =IF($A9="","",VALUE(MID($A9,FIND(E$1,$A9)+LEN(E$1),FIND(E$2,$A9,FIND(E$1,$A9))-(FIND(E$1,$A9)+LEN(E$1))))) -> 23 | F9: =IF($A9="","",VALUE(MID($A9,FIND(F$1,$A9)+LEN(F$1),FIND(F$2,$A9,FIND(F$1,$A9))-(FIND(F$1,$A9)+LEN(F$1))))) -> 19 | G9: =IF($A9="","",VALUE(MID($A9,FIND(G$1,$A9)+LEN(G$1),FIND(G$2,$A9,FIND(G$1,$A9))-(FIND(G$1,$A9)+LEN(G$1))))) -> 18 | H9: =IF($A9="","",VALUE(MID($A9,FIND(H$1,$A9)+LEN(H$1),FIND(H$2,$A9,FIND(H$1,$A9))-(FIND(H$1,$A9)+LEN(H$1))))) -> 1646 | I9: =IF($A9="","",VALUE(MID($A9,FIND(I$1,$A9)+LEN(I$1),FIND(I$2,$A9,FIND(I$1,$A9))-(FIND(I$1,$A9)+LEN(I$1))))) -> 1370 | J9: =IF(OR($D9="",$E9=""),"",$E9^2+2*$E9*$D9-$D9^2) -> 1022 | K9: =IF($A9="","",VALUE(MID($A9,FIND(K$1,$A9)+LEN(K$1),FIND(K$2,$A9,FIND(K$1,$A9))-(FIND(K$1,$A9)+LEN(K$1))))) -> 721 | L9: =IF($A9="","",VALUE(MID($A9,FIND(L$1,$A9)+LEN(L$1),FIND(L$2,$A9,FIND(L$1,$A9))-(FIND(L$1,$A9)+LEN(L$1))))) -> 685 | M9: =IF(OR($F9="",$G9=""),"",$G9^2+2*$G9*$F9-$F9^2) -> 647 | N9: =IF(OR($H9="",$I9="",$J9="",$K9="",$L9="",$M9=""),"",GCD($H9:$M9)) -> 1 | O9: =IF($A9="","",MID($A9,FIND(" ",$A9,FIND(L$1,$A9))+1,1)) -> D | P9: =IF(A9="","",TRIM(SUBSTITUTE(SUBSTITUTE(RIGHT(A9,LEN(A9)-FIND("=",A9,FIND("]",A9,FIND("]",A9)+1))),"^2",""),".",""))) -> 67,130 | Q9: =IF(OR($H9="",$L9="",$N9=""),"",$H9*$L9/$N9) -> 1127510 | R9: =IF(OR($K9="",$I9="",$N9=""),"",$K9*$I9/$N9) -> 987770 | S9: =IF(OR($O9<>UPPER(S$2),$N9=""),"",IF($P9="",-1,$P9/$N9)) | T9: =IF(OR($O9<>UPPER(T$2),$N9=""),"",IF($P9="",-1,$P9/$N9)) -> 67130 | U9: =IF(OR($I9="",$L9="",$N9=""),"",$I9*$L9/$N9) -> 938450 | V9: =IF(OR($O9<>UPPER(V$2),$N9=""),"",IF($P9="",-1,$P9/$N9)) | W9: =IF(OR($O9<>UPPER(W$2),$N9=""),"",IF($P9="",-1,$P9/$N9)) | X9: =IF(OR($M9="",$I9="",$N9=""),"",$M9*$I9/$N9) -> 886390 | Y9: =IF(OR($J9="",$L9="",$N9=""),"",$J9*$L9/$N9) -> 700070
A10: At [Seeds: j_a=29 k_a=26 j_b=11 k_b=8], [Entries: l_a=1,673 e_a=1,517 l_b=233 e_b=185], C=124,727^2. | B10: =IF(A10="","",IF(COUNTIF(C$2:C9,C10)>0,"Duplicate",IF(LEFT(C10,LEN(C10)-1)=LEFT(OFFSET(C10,-1,0),LEN(OFFSET(C10,-1,0))-1),"2 Sols",""))) | C10: =IF(A10="","",RIGHT("00000"&IF(OR($D10="",$E10="",$F10="",$G10=""),"",IF($D10>=$F10,$D10,$F10)),5)&"-" &RIGHT("00000"&IF(OR($D10="",$E10="",$F10="",$G10=""),"",IF($D10=$F10,IF($E10>=$G10,$E10,$G10),IF($D10>$F10,$E10,$G10))),5)&"-" &RIGHT("00000"&IF(OR($D10="",$E10="",$F10="",$G10=""),"",IF($D10<$F10,$D10,$F10)),5)&"-" &RIGHT("00000"&IF(OR($D10="",$E10="",$F10="",$G10=""),"",IF($D10=$F10,IF($E10<$G10,$E10,$G10),IF($D10<$F10,$E10,$G10))),5)&"-"&O10) -> 00029-00026-00011-00008-C | D10: =IF($A10="","",VALUE(MID($A10,FIND(D$1,$A10)+LEN(D$1),FIND(D$2,$A10,FIND(D$1,$A10))-(FIND(D$1,$A10)+LEN(D$1))))) -> 29 | E10: =IF($A10="","",VALUE(MID($A10,FIND(E$1,$A10)+LEN(E$1),FIND(E$2,$A10,FIND(E$1,$A10))-(FIND(E$1,$A10)+LEN(E$1))))) -> 26 | F10: =IF($A10="","",VALUE(MID($A10,FIND(F$1,$A10)+LEN(F$1),FIND(F$2,$A10,FIND(F$1,$A10))-(FIND(F$1,$A10)+LEN(F$1))))) -> 11 | G10: =IF($A10="","",VALUE(MID($A10,FIND(G$1,$A10)+LEN(G$1),FIND(G$2,$A10,FIND(G$1,$A10))-(FIND(G$1,$A10)+LEN(G$1))))) -> 8 | H10: =IF($A10="","",VALUE(MID($A10,FIND(H$1,$A10)+LEN(H$1),FIND(H$2,$A10,FIND(H$1,$A10))-(FIND(H$1,$A10)+LEN(H$1))))) -> 1673 | I10: =IF($A10="","",VALUE(MID($A10,FIND(I$1,$A10)+LEN(I$1),FIND(I$2,$A10,FIND(I$1,$A10))-(FIND(I$1,$A10)+LEN(I$1))))) -> 1517 | J10: =IF(OR($D10="",$E10=""),"",$E10^2+2*$E10*$D10-$D10^2) -> 1343 | K10: =IF($A10="","",VALUE(MID($A10,FIND(K$1,$A10)+LEN(K$1),FIND(K$2,$A10,FIND(K$1,$A10))-(FIND(K$1,$A10)+LEN(K$1))))) -> 233 | L10: =IF($A10="","",VALUE(MID($A10,FIND(L$1,$A10)+LEN(L$1),FIND(L$2,$A10,FIND(L$1,$A10))-(FIND(L$1,$A10)+LEN(L$1))))) -> 185 | M10: =IF(OR($F10="",$G10=""),"",$G10^2+2*$G10*$F10-$F10^2) -> 119 | N10: =IF(OR($H10="",$I10="",$J10="",$K10="",$L10="",$M10=""),"",GCD($H10:$M10)) -> 1 | O10: =IF($A10="","",MID($A10,FIND(" ",$A10,FIND(L$1,$A10))+1,1)) -> C | P10: =IF(A10="","",TRIM(SUBSTITUTE(SUBSTITUTE(RIGHT(A10,LEN(A10)-FIND("=",A10,FIND("]",A10,FIND("]",A10)+1))),"^2",""),".",""))) -> 124,727 | Q10: =IF(OR($H10="",$L10="",$N10=""),"",$H10*$L10/$N10) -> 309505 | R10: =IF(OR($K10="",$I10="",$N10=""),"",$K10*$I10/$N10) -> 353461 | S10: =IF(OR($O10<>UPPER(S$2),$N10=""),"",IF($P10="",-1,$P10/$N10)) -> 124727 | T10: =IF(OR($O10<>UPPER(T$2),$N10=""),"",IF($P10="",-1,$P10/$N10)) | U10: =IF(OR($I10="",$L10="",$N10=""),"",$I10*$L10/$N10) -> 280645 | V10: =IF(OR($O10<>UPPER(V$2),$N10=""),"",IF($P10="",-1,$P10/$N10)) | W10: =IF(OR($O10<>UPPER(W$2),$N10=""),"",IF($P10="",-1,$P10/$N10)) | X10: =IF(OR($M10="",$I10="",$N10=""),"",$M10*$I10/$N10) -> 180523 | Y10: =IF(OR($J10="",$L10="",$N10=""),"",$J10*$L10/$N10) -> 248455
A11: At [Seeds: j_a=31 k_a=29 j_b=11 k_b=7], [Entries: l_a=1,918 e_a=1,802 l_b=226 e_b=170], C=96,764^2. | B11: =IF(A11="","",IF(COUNTIF(C$2:C10,C11)>0,"Duplicate",IF(LEFT(C11,LEN(C11)-1)=LEFT(OFFSET(C11,-1,0),LEN(OFFSET(C11,-1,0))-1),"2 Sols",""))) | C11: =IF(A11="","",RIGHT("00000"&IF(OR($D11="",$E11="",$F11="",$G11=""),"",IF($D11>=$F11,$D11,$F11)),5)&"-" &RIGHT("00000"&IF(OR($D11="",$E11="",$F11="",$G11=""),"",IF($D11=$F11,IF($E11>=$G11,$E11,$G11),IF($D11>$F11,$E11,$G11))),5)&"-" &RIGHT("00000"&IF(OR($D11="",$E11="",$F11="",$G11=""),"",IF($D11<$F11,$D11,$F11)),5)&"-" &RIGHT("00000"&IF(OR($D11="",$E11="",$F11="",$G11=""),"",IF($D11=$F11,IF($E11<$G11,$E11,$G11),IF($D11<$F11,$E11,$G11))),5)&"-"&O11) -> 00031-00029-00011-00007-C | D11: =IF($A11="","",VALUE(MID($A11,FIND(D$1,$A11)+LEN(D$1),FIND(D$2,$A11,FIND(D$1,$A11))-(FIND(D$1,$A11)+LEN(D$1))))) -> 31 | E11: =IF($A11="","",VALUE(MID($A11,FIND(E$1,$A11)+LEN(E$1),FIND(E$2,$A11,FIND(E$1,$A11))-(FIND(E$1,$A11)+LEN(E$1))))) -> 29 | F11: =IF($A11="","",VALUE(MID($A11,FIND(F$1,$A11)+LEN(F$1),FIND(F$2,$A11,FIND(F$1,$A11))-(FIND(F$1,$A11)+LEN(F$1))))) -> 11 | G11: =IF($A11="","",VALUE(MID($A11,FIND(G$1,$A11)+LEN(G$1),FIND(G$2,$A11,FIND(G$1,$A11))-(FIND(G$1,$A11)+LEN(G$1))))) -> 7 | H11: =IF($A11="","",VALUE(MID($A11,FIND(H$1,$A11)+LEN(H$1),FIND(H$2,$A11,FIND(H$1,$A11))-(FIND(H$1,$A11)+LEN(H$1))))) -> 1918 | I11: =IF($A11="","",VALUE(MID($A11,FIND(I$1,$A11)+LEN(I$1),FIND(I$2,$A11,FIND(I$1,$A11))-(FIND(I$1,$A11)+LEN(I$1))))) -> 1802 | J11: =IF(OR($D11="",$E11=""),"",$E11^2+2*$E11*$D11-$D11^2) -> 1678 | K11: =IF($A11="","",VALUE(MID($A11,FIND(K$1,$A11)+LEN(K$1),FIND(K$2,$A11,FIND(K$1,$A11))-(FIND(K$1,$A11)+LEN(K$1))))) -> 226 | L11: =IF($A11="","",VALUE(MID($A11,FIND(L$1,$A11)+LEN(L$1),FIND(L$2,$A11,FIND(L$1,$A11))-(FIND(L$1,$A11)+LEN(L$1))))) -> 170 | M11: =IF(OR($F11="",$G11=""),"",$G11^2+2*$G11*$F11-$F11^2) -> 82 | N11: =IF(OR($H11="",$I11="",$J11="",$K11="",$L11="",$M11=""),"",GCD($H11:$M11)) -> 2 | O11: =IF($A11="","",MID($A11,FIND(" ",$A11,FIND(L$1,$A11))+1,1)) -> C | P11: =IF(A11="","",TRIM(SUBSTITUTE(SUBSTITUTE(RIGHT(A11,LEN(A11)-FIND("=",A11,FIND("]",A11,FIND("]",A11)+1))),"^2",""),".",""))) -> 96,764 | Q11: =IF(OR($H11="",$L11="",$N11=""),"",$H11*$L11/$N11) -> 163030 | R11: =IF(OR($K11="",$I11="",$N11=""),"",$K11*$I11/$N11) -> 203626 | S11: =IF(OR($O11<>UPPER(S$2),$N11=""),"",IF($P11="",-1,$P11/$N11)) -> 48382 | T11: =IF(OR($O11<>UPPER(T$2),$N11=""),"",IF($P11="",-1,$P11/$N11)) | U11: =IF(OR($I11="",$L11="",$N11=""),"",$I11*$L11/$N11) -> 153170 | V11: =IF(OR($O11<>UPPER(V$2),$N11=""),"",IF($P11="",-1,$P11/$N11)) | W11: =IF(OR($O11<>UPPER(W$2),$N11=""),"",IF($P11="",-1,$P11/$N11)) | X11: =IF(OR($M11="",$I11="",$N11=""),"",$M11*$I11/$N11) -> 73882 | Y11: =IF(OR($J11="",$L11="",$N11=""),"",$J11*$L11/$N11) -> 142630
A12: At [Seeds: j_a=31 k_a=29 j_b=26 k_b=15], [Entries: l_a=1,918 e_a=1,802 l_b=1,231 e_b=901], C=34,238^2. | B12: =IF(A12="","",IF(COUNTIF(C$2:C11,C12)>0,"Duplicate",IF(LEFT(C12,LEN(C12)-1)=LEFT(OFFSET(C12,-1,0),LEN(OFFSET(C12,-1,0))-1),"2 Sols",""))) | C12: =IF(A12="","",RIGHT("00000"&IF(OR($D12="",$E12="",$F12="",$G12=""),"",IF($D12>=$F12,$D12,$F12)),5)&"-" &RIGHT("00000"&IF(OR($D12="",$E12="",$F12="",$G12=""),"",IF($D12=$F12,IF($E12>=$G12,$E12,$G12),IF($D12>$F12,$E12,$G12))),5)&"-" &RIGHT("00000"&IF(OR($D12="",$E12="",$F12="",$G12=""),"",IF($D12<$F12,$D12,$F12)),5)&"-" &RIGHT("00000"&IF(OR($D12="",$E12="",$F12="",$G12=""),"",IF($D12=$F12,IF($E12<$G12,$E12,$G12),IF($D12<$F12,$E12,$G12))),5)&"-"&O12) -> 00031-00029-00026-00015-C | D12: =IF($A12="","",VALUE(MID($A12,FIND(D$1,$A12)+LEN(D$1),FIND(D$2,$A12,FIND(D$1,$A12))-(FIND(D$1,$A12)+LEN(D$1))))) -> 31 | E12: =IF($A12="","",VALUE(MID($A12,FIND(E$1,$A12)+LEN(E$1),FIND(E$2,$A12,FIND(E$1,$A12))-(FIND(E$1,$A12)+LEN(E$1))))) -> 29 | F12: =IF($A12="","",VALUE(MID($A12,FIND(F$1,$A12)+LEN(F$1),FIND(F$2,$A12,FIND(F$1,$A12))-(FIND(F$1,$A12)+LEN(F$1))))) -> 26 | G12: =IF($A12="","",VALUE(MID($A12,FIND(G$1,$A12)+LEN(G$1),FIND(G$2,$A12,FIND(G$1,$A12))-(FIND(G$1,$A12)+LEN(G$1))))) -> 15 | H12: =IF($A12="","",VALUE(MID($A12,FIND(H$1,$A12)+LEN(H$1),FIND(H$2,$A12,FIND(H$1,$A12))-(FIND(H$1,$A12)+LEN(H$1))))) -> 1918 | I12: =IF($A12="","",VALUE(MID($A12,FIND(I$1,$A12)+LEN(I$1),FIND(I$2,$A12,FIND(I$1,$A12))-(FIND(I$1,$A12)+LEN(I$1))))) -> 1802 | J12: =IF(OR($D12="",$E12=""),"",$E12^2+2*$E12*$D12-$D12^2) -> 1678 | K12: =IF($A12="","",VALUE(MID($A12,FIND(K$1,$A12)+LEN(K$1),FIND(K$2,$A12,FIND(K$1,$A12))-(FIND(K$1,$A12)+LEN(K$1))))) -> 1231 | L12: =IF($A12="","",VALUE(MID($A12,FIND(L$1,$A12)+LEN(L$1),FIND(L$2,$A12,FIND(L$1,$A12))-(FIND(L$1,$A12)+LEN(L$1))))) -> 901 | M12: =IF(OR($F12="",$G12=""),"",$G12^2+2*$G12*$F12-$F12^2) -> 329 | N12: =IF(OR($H12="",$I12="",$J12="",$K12="",$L12="",$M12=""),"",GCD($H12:$M12)) -> 1 | O12: =IF($A12="","",MID($A12,FIND(" ",$A12,FIND(L$1,$A12))+1,1)) -> C | P12: =IF(A12="","",TRIM(SUBSTITUTE(SUBSTITUTE(RIGHT(A12,LEN(A12)-FIND("=",A12,FIND("]",A12,FIND("]",A12)+1))),"^2",""),".",""))) -> 34,238 | Q12: =IF(OR($H12="",$L12="",$N12=""),"",$H12*$L12/$N12) -> 1728118 | R12: =IF(OR($K12="",$I12="",$N12=""),"",$K12*$I12/$N12) -> 2218262 | S12: =IF(OR($O12<>UPPER(S$2),$N12=""),"",IF($P12="",-1,$P12/$N12)) -> 34238 | T12: =IF(OR($O12<>UPPER(T$2),$N12=""),"",IF($P12="",-1,$P12/$N12)) | U12: =IF(OR($I12="",$L12="",$N12=""),"",$I12*$L12/$N12) -> 1623602 | V12: =IF(OR($O12<>UPPER(V$2),$N12=""),"",IF($P12="",-1,$P12/$N12)) | W12: =IF(OR($O12<>UPPER(W$2),$N12=""),"",IF($P12="",-1,$P12/$N12)) | X12: =IF(OR($M12="",$I12="",$N12=""),"",$M12*$I12/$N12) -> 592858 | Y12: =IF(OR($J12="",$L12="",$N12=""),"",$J12*$L12/$N12) -> 1511878
A13: At [Seeds: j_a=33 k_a=32 j_b=5 k_b=3], [Entries: l_a=2,177 e_a=2,113 l_b=46 e_b=34], D=15,502^2. | B13: =IF(A13="","",IF(COUNTIF(C$2:C12,C13)>0,"Duplicate",IF(LEFT(C13,LEN(C13)-1)=LEFT(OFFSET(C13,-1,0),LEN(OFFSET(C13,-1,0))-1),"2 Sols",""))) | C13: =IF(A13="","",RIGHT("00000"&IF(OR($D13="",$E13="",$F13="",$G13=""),"",IF($D13>=$F13,$D13,$F13)),5)&"-" &RIGHT("00000"&IF(OR($D13="",$E13="",$F13="",$G13=""),"",IF($D13=$F13,IF($E13>=$G13,$E13,$G13),IF($D13>$F13,$E13,$G13))),5)&"-" &RIGHT("00000"&IF(OR($D13="",$E13="",$F13="",$G13=""),"",IF($D13<$F13,$D13,$F13)),5)&"-" &RIGHT("00000"&IF(OR($D13="",$E13="",$F13="",$G13=""),"",IF($D13=$F13,IF($E13<$G13,$E13,$G13),IF($D13<$F13,$E13,$G13))),5)&"-"&O13) -> 00033-00032-00005-00003-D | D13: =IF($A13="","",VALUE(MID($A13,FIND(D$1,$A13)+LEN(D$1),FIND(D$2,$A13,FIND(D$1,$A13))-(FIND(D$1,$A13)+LEN(D$1))))) -> 33 | E13: =IF($A13="","",VALUE(MID($A13,FIND(E$1,$A13)+LEN(E$1),FIND(E$2,$A13,FIND(E$1,$A13))-(FIND(E$1,$A13)+LEN(E$1))))) -> 32 | F13: =IF($A13="","",VALUE(MID($A13,FIND(F$1,$A13)+LEN(F$1),FIND(F$2,$A13,FIND(F$1,$A13))-(FIND(F$1,$A13)+LEN(F$1))))) -> 5 | G13: =IF($A13="","",VALUE(MID($A13,FIND(G$1,$A13)+LEN(G$1),FIND(G$2,$A13,FIND(G$1,$A13))-(FIND(G$1,$A13)+LEN(G$1))))) -> 3 | H13: =IF($A13="","",VALUE(MID($A13,FIND(H$1,$A13)+LEN(H$1),FIND(H$2,$A13,FIND(H$1,$A13))-(FIND(H$1,$A13)+LEN(H$1))))) -> 2177 | I13: =IF($A13="","",VALUE(MID($A13,FIND(I$1,$A13)+LEN(I$1),FIND(I$2,$A13,FIND(I$1,$A13))-(FIND(I$1,$A13)+LEN(I$1))))) -> 2113 | J13: =IF(OR($D13="",$E13=""),"",$E13^2+2*$E13*$D13-$D13^2) -> 2047 | K13: =IF($A13="","",VALUE(MID($A13,FIND(K$1,$A13)+LEN(K$1),FIND(K$2,$A13,FIND(K$1,$A13))-(FIND(K$1,$A13)+LEN(K$1))))) -> 46 | L13: =IF($A13="","",VALUE(MID($A13,FIND(L$1,$A13)+LEN(L$1),FIND(L$2,$A13,FIND(L$1,$A13))-(FIND(L$1,$A13)+LEN(L$1))))) -> 34 | M13: =IF(OR($F13="",$G13=""),"",$G13^2+2*$G13*$F13-$F13^2) -> 14 | N13: =IF(OR($H13="",$I13="",$J13="",$K13="",$L13="",$M13=""),"",GCD($H13:$M13)) -> 1 | O13: =IF($A13="","",MID($A13,FIND(" ",$A13,FIND(L$1,$A13))+1,1)) -> D | P13: =IF(A13="","",TRIM(SUBSTITUTE(SUBSTITUTE(RIGHT(A13,LEN(A13)-FIND("=",A13,FIND("]",A13,FIND("]",A13)+1))),"^2",""),".",""))) -> 15,502 | Q13: =IF(OR($H13="",$L13="",$N13=""),"",$H13*$L13/$N13) -> 74018 | R13: =IF(OR($K13="",$I13="",$N13=""),"",$K13*$I13/$N13) -> 97198 | S13: =IF(OR($O13<>UPPER(S$2),$N13=""),"",IF($P13="",-1,$P13/$N13)) | T13: =IF(OR($O13<>UPPER(T$2),$N13=""),"",IF($P13="",-1,$P13/$N13)) -> 15502 | U13: =IF(OR($I13="",$L13="",$N13=""),"",$I13*$L13/$N13) -> 71842 | V13: =IF(OR($O13<>UPPER(V$2),$N13=""),"",IF($P13="",-1,$P13/$N13)) | W13: =IF(OR($O13<>UPPER(W$2),$N13=""),"",IF($P13="",-1,$P13/$N13)) | X13: =IF(OR($M13="",$I13="",$N13=""),"",$M13*$I13/$N13) -> 29582 | Y13: =IF(OR($J13="",$L13="",$N13=""),"",$J13*$L13/$N13) -> 69598
A14: At [Seeds: j_a=36 k_a=25 j_b=8 k_b=7], [Entries: l_a=2,471 e_a=1,921 l_b=127 e_b=113], C=62,263^2. | B14: =IF(A14="","",IF(COUNTIF(C$2:C13,C14)>0,"Duplicate",IF(LEFT(C14,LEN(C14)-1)=LEFT(OFFSET(C14,-1,0),LEN(OFFSET(C14,-1,0))-1),"2 Sols",""))) | C14: =IF(A14="","",RIGHT("00000"&IF(OR($D14="",$E14="",$F14="",$G14=""),"",IF($D14>=$F14,$D14,$F14)),5)&"-" &RIGHT("00000"&IF(OR($D14="",$E14="",$F14="",$G14=""),"",IF($D14=$F14,IF($E14>=$G14,$E14,$G14),IF($D14>$F14,$E14,$G14))),5)&"-" &RIGHT("00000"&IF(OR($D14="",$E14="",$F14="",$G14=""),"",IF($D14<$F14,$D14,$F14)),5)&"-" &RIGHT("00000"&IF(OR($D14="",$E14="",$F14="",$G14=""),"",IF($D14=$F14,IF($E14<$G14,$E14,$G14),IF($D14<$F14,$E14,$G14))),5)&"-"&O14) -> 00036-00025-00008-00007-C | D14: =IF($A14="","",VALUE(MID($A14,FIND(D$1,$A14)+LEN(D$1),FIND(D$2,$A14,FIND(D$1,$A14))-(FIND(D$1,$A14)+LEN(D$1))))) -> 36 | E14: =IF($A14="","",VALUE(MID($A14,FIND(E$1,$A14)+LEN(E$1),FIND(E$2,$A14,FIND(E$1,$A14))-(FIND(E$1,$A14)+LEN(E$1))))) -> 25 | F14: =IF($A14="","",VALUE(MID($A14,FIND(F$1,$A14)+LEN(F$1),FIND(F$2,$A14,FIND(F$1,$A14))-(FIND(F$1,$A14)+LEN(F$1))))) -> 8 | G14: =IF($A14="","",VALUE(MID($A14,FIND(G$1,$A14)+LEN(G$1),FIND(G$2,$A14,FIND(G$1,$A14))-(FIND(G$1,$A14)+LEN(G$1))))) -> 7 | H14: =IF($A14="","",VALUE(MID($A14,FIND(H$1,$A14)+LEN(H$1),FIND(H$2,$A14,FIND(H$1,$A14))-(FIND(H$1,$A14)+LEN(H$1))))) -> 2471 | I14: =IF($A14="","",VALUE(MID($A14,FIND(I$1,$A14)+LEN(I$1),FIND(I$2,$A14,FIND(I$1,$A14))-(FIND(I$1,$A14)+LEN(I$1))))) -> 1921 | J14: =IF(OR($D14="",$E14=""),"",$E14^2+2*$E14*$D14-$D14^2) -> 1129 | K14: =IF($A14="","",VALUE(MID($A14,FIND(K$1,$A14)+LEN(K$1),FIND(K$2,$A14,FIND(K$1,$A14))-(FIND(K$1,$A14)+LEN(K$1))))) -> 127 | L14: =IF($A14="","",VALUE(MID($A14,FIND(L$1,$A14)+LEN(L$1),FIND(L$2,$A14,FIND(L$1,$A14))-(FIND(L$1,$A14)+LEN(L$1))))) -> 113 | M14: =IF(OR($F14="",$G14=""),"",$G14^2+2*$G14*$F14-$F14^2) -> 97 | N14: =IF(OR($H14="",$I14="",$J14="",$K14="",$L14="",$M14=""),"",GCD($H14:$M14)) -> 1 | O14: =IF($A14="","",MID($A14,FIND(" ",$A14,FIND(L$1,$A14))+1,1)) -> C | P14: =IF(A14="","",TRIM(SUBSTITUTE(SUBSTITUTE(RIGHT(A14,LEN(A14)-FIND("=",A14,FIND("]",A14,FIND("]",A14)+1))),"^2",""),".",""))) -> 62,263 | Q14: =IF(OR($H14="",$L14="",$N14=""),"",$H14*$L14/$N14) -> 279223 | R14: =IF(OR($K14="",$I14="",$N14=""),"",$K14*$I14/$N14) -> 243967 | S14: =IF(OR($O14<>UPPER(S$2),$N14=""),"",IF($P14="",-1,$P14/$N14)) -> 62263 | T14: =IF(OR($O14<>UPPER(T$2),$N14=""),"",IF($P14="",-1,$P14/$N14)) | U14: =IF(OR($I14="",$L14="",$N14=""),"",$I14*$L14/$N14) -> 217073 | V14: =IF(OR($O14<>UPPER(V$2),$N14=""),"",IF($P14="",-1,$P14/$N14)) | W14: =IF(OR($O14<>UPPER(W$2),$N14=""),"",IF($P14="",-1,$P14/$N14)) | X14: =IF(OR($M14="",$I14="",$N14=""),"",$M14*$I14/$N14) -> 186337 | Y14: =IF(OR($J14="",$L14="",$N14=""),"",$J14*$L14/$N14) -> 127577
... A2217: At [Seeds: j_a=1,705 k_a=1,146 j_b=1,667 k_b=1,572], [Entries: l_a=5,501,569 e_a=4,220,341 l_b=5,548,753 e_b=5,250,073], C=9,495,316,796,857^2. | B2217: =IF(A2217="","",IF(COUNTIF(C$2:C2216,C2217)>0,"Duplicate",IF(LEFT(C2217,LEN(C2217)-1)=LEFT(OFFSET(C2217,-1,0),LEN(OFFSET(C2217,-1,0))-1),"2 Sols",""))) | C2217: =IF(A2217="","",RIGHT("00000"&IF(OR($D2217="",$E2217="",$F2217="",$G2217=""),"",IF($D2217>=$F2217,$D2217,$F2217)),5)&"-" &RIGHT("00000"&IF(OR($D2217="",$E2217="",$F2217="",$G2217=""),"",IF($D2217=$F2217,IF($E2217>=$G2217,$E2217,$G2217),IF($D2217>$F2217,$E2217,$G2217))),5)&"-" &RIGHT("00000"&IF(OR($D2217="",$E2217="",$F2217="",$G2217=""),"",IF($D2217<$F2217,$D2217,$F2217)),5)&"-" &RIGHT("00000"&IF(OR($D2217="",$E2217="",$F2217="",$G2217=""),"",IF($D2217=$F2217,IF($E2217<$G2217,$E2217,$G2217),IF($D2217<$F2217,$E2217,$G2217))),5)&"-"&O2217) -> 01705-01146-01667-01572-C | D2217: =IF($A2217="","",VALUE(MID($A2217,FIND(D$1,$A2217)+LEN(D$1),FIND(D$2,$A2217,FIND(D$1,$A2217))-(FIND(D$1,$A2217)+LEN(D$1))))) -> 1705 | E2217: =IF($A2217="","",VALUE(MID($A2217,FIND(E$1,$A2217)+LEN(E$1),FIND(E$2,$A2217,FIND(E$1,$A2217))-(FIND(E$1,$A2217)+LEN(E$1))))) -> 1146 | F2217: =IF($A2217="","",VALUE(MID($A2217,FIND(F$1,$A2217)+LEN(F$1),FIND(F$2,$A2217,FIND(F$1,$A2217))-(FIND(F$1,$A2217)+LEN(F$1))))) -> 1667 | G2217: =IF($A2217="","",VALUE(MID($A2217,FIND(G$1,$A2217)+LEN(G$1),FIND(G$2,$A2217,FIND(G$1,$A2217))-(FIND(G$1,$A2217)+LEN(G$1))))) -> 1572 | H2217: =IF($A2217="","",VALUE(MID($A2217,FIND(H$1,$A2217)+LEN(H$1),FIND(H$2,$A2217,FIND(H$1,$A2217))-(FIND(H$1,$A2217)+LEN(H$1))))) -> 5501569 | I2217: =IF($A2217="","",VALUE(MID($A2217,FIND(I$1,$A2217)+LEN(I$1),FIND(I$2,$A2217,FIND(I$1,$A2217))-(FIND(I$1,$A2217)+LEN(I$1))))) -> 4220341 | J2217: =IF(OR($D2217="",$E2217=""),"",$E2217^2+2*$E2217*$D2217-$D2217^2) -> 2314151 | K2217: =IF($A2217="","",VALUE(MID($A2217,FIND(K$1,$A2217)+LEN(K$1),FIND(K$2,$A2217,FIND(K$1,$A2217))-(FIND(K$1,$A2217)+LEN(K$1))))) -> 5548753 | L2217: =IF($A2217="","",VALUE(MID($A2217,FIND(L$1,$A2217)+LEN(L$1),FIND(L$2,$A2217,FIND(L$1,$A2217))-(FIND(L$1,$A2217)+LEN(L$1))))) -> 5250073 | M2217: =IF(OR($F2217="",$G2217=""),"",$G2217^2+2*$G2217*$F2217-$F2217^2) -> 4933343 | N2217: =IF(OR($H2217="",$I2217="",$J2217="",$K2217="",$L2217="",$M2217=""),"",GCD($H2217:$M2217)) -> 1 | O2217: =IF($A2217="","",MID($A2217,FIND(" ",$A2217,FIND(L$1,$A2217))+1,1)) -> C | P2217: =IF(A2217="","",TRIM(SUBSTITUTE(SUBSTITUTE(RIGHT(A2217,LEN(A2217)-FIND("=",A2217,FIND("]",A2217,FIND("]",A2217)+1))),"^2",""),".",""))) -> 9,495,316,796,857 | Q2217: =IF(OR($H2217="",$L2217="",$N2217=""),"",$H2217*$L2217/$N2217) -> 28883638864537 | R2217: =IF(OR($K2217="",$I2217="",$N2217=""),"",$K2217*$I2217/$N2217) -> 23417629784773 | S2217: =IF(OR($O2217<>UPPER(S$2),$N2217=""),"",IF($P2217="",-1,$P2217/$N2217)) -> 9495316796857 | T2217: =IF(OR($O2217<>UPPER(T$2),$N2217=""),"",IF($P2217="",-1,$P2217/$N2217)) | U2217: =IF(OR($I2217="",$L2217="",$N2217=""),"",$I2217*$L2217/$N2217) -> 22157098334893 | V2217: =IF(OR($O2217<>UPPER(V$2),$N2217=""),"",IF($P2217="",-1,$P2217/$N2217)) | W2217: =IF(OR($O2217<>UPPER(W$2),$N2217=""),"",IF($P2217="",-1,$P2217/$N2217)) | X2217: =IF(OR($M2217="",$I2217="",$N2217=""),"",$M2217*$I2217/$N2217) -> 20820389729963 | Y2217: =IF(OR($J2217="",$L2217="",$N2217=""),"",$J2217*$L2217/$N2217) -> 12149461683023
B2218: =IF(A2218="","",IF(COUNTIF(C$2:C2217,C2218)>0,"Duplicate",IF(LEFT(C2218,LEN(C2218)-1)=LEFT(OFFSET(C2218,-1,0),LEN(OFFSET(C2218,-1,0))-1),"2 Sols",""))) | C2218: =IF(A2218="","",RIGHT("00000"&IF(OR($D2218="",$E2218="",$F2218="",$G2218=""),"",IF($D2218>=$F2218,$D2218,$F2218)),5)&"-" &RIGHT("00000"&IF(OR($D2218="",$E2218="",$F2218="",$G2218=""),"",IF($D2218=$F2218,IF($E2218>=$G2218,$E2218,$G2218),IF($D2218>$F2218,$E2218,$G2218))),5)&"-" &RIGHT("00000"&IF(OR($D2218="",$E2218="",$F2218="",$G2218=""),"",IF($D2218<$F2218,$D2218,$F2218)),5)&"-" &RIGHT("00000"&IF(OR($D2218="",$E2218="",$F2218="",$G2218=""),"",IF($D2218=$F2218,IF($E2218<$G2218,$E2218,$G2218),IF($D2218<$F2218,$E2218,$G2218))),5)&"-"&O2218) | D2218: =IF($A2218="","",VALUE(MID($A2218,FIND(D$1,$A2218)+LEN(D$1),FIND(D$2,$A2218,FIND(D$1,$A2218))-(FIND(D$1,$A2218)+LEN(D$1))))) | E2218: =IF($A2218="","",VALUE(MID($A2218,FIND(E$1,$A2218)+LEN(E$1),FIND(E$2,$A2218,FIND(E$1,$A2218))-(FIND(E$1,$A2218)+LEN(E$1))))) | F2218: =IF($A2218="","",VALUE(MID($A2218,FIND(F$1,$A2218)+LEN(F$1),FIND(F$2,$A2218,FIND(F$1,$A2218))-(FIND(F$1,$A2218)+LEN(F$1))))) | G2218: =IF($A2218="","",VALUE(MID($A2218,FIND(G$1,$A2218)+LEN(G$1),FIND(G$2,$A2218,FIND(G$1,$A2218))-(FIND(G$1,$A2218)+LEN(G$1))))) | H2218: =IF($A2218="","",VALUE(MID($A2218,FIND(H$1,$A2218)+LEN(H$1),FIND(H$2,$A2218,FIND(H$1,$A2218))-(FIND(H$1,$A2218)+LEN(H$1))))) | I2218: =IF($A2218="","",VALUE(MID($A2218,FIND(I$1,$A2218)+LEN(I$1),FIND(I$2,$A2218,FIND(I$1,$A2218))-(FIND(I$1,$A2218)+LEN(I$1))))) | J2218: =IF(OR($D2218="",$E2218=""),"",$E2218^2+2*$E2218*$D2218-$D2218^2) | K2218: =IF($A2218="","",VALUE(MID($A2218,FIND(K$1,$A2218)+LEN(K$1),FIND(K$2,$A2218,FIND(K$1,$A2218))-(FIND(K$1,$A2218)+LEN(K$1))))) | L2218: =IF($A2218="","",VALUE(MID($A2218,FIND(L$1,$A2218)+LEN(L$1),FIND(L$2,$A2218,FIND(L$1,$A2218))-(FIND(L$1,$A2218)+LEN(L$1))))) | M2218: =IF(OR($F2218="",$G2218=""),"",$G2218^2+2*$G2218*$F2218-$F2218^2) | N2218: =IF(OR($H2218="",$I2218="",$J2218="",$K2218="",$L2218="",$M2218=""),"",GCD($H2218:$M2218)) | O2218: =IF($A2218="","",MID($A2218,FIND(" ",$A2218,FIND(L$1,$A2218))+1,1)) | P2218: =IF(A2218="","",TRIM(SUBSTITUTE(SUBSTITUTE(RIGHT(A2218,LEN(A2218)-FIND("=",A2218,FIND("]",A2218,FIND("]",A2218)+1))),"^2",""),".",""))) | Q2218: =IF(OR($H2218="",$L2218="",$N2218=""),"",$H2218*$L2218/$N2218) | R2218: =IF(OR($K2218="",$I2218="",$N2218=""),"",$K2218*$I2218/$N2218) | S2218: =IF(OR($O2218<>UPPER(S$2),$N2218=""),"",IF($P2218="",-1,$P2218/$N2218)) | T2218: =IF(OR($O2218<>UPPER(T$2),$N2218=""),"",IF($P2218="",-1,$P2218/$N2218)) | U2218: =IF(OR($I2218="",$L2218="",$N2218=""),"",$I2218*$L2218/$N2218) | V2218: =IF(OR($O2218<>UPPER(V$2),$N2218=""),"",IF($P2218="",-1,$P2218/$N2218)) | W2218: =IF(OR($O2218<>UPPER(W$2),$N2218=""),"",IF($P2218="",-1,$P2218/$N2218)) | X2218: =IF(OR($M2218="",$I2218="",$N2218=""),"",$M2218*$I2218/$N2218) | Y2218: =IF(OR($J2218="",$L2218="",$N2218=""),"",$J2218*$L2218/$N2218)
B2219: =IF(A2219="","",IF(COUNTIF(C$2:C2218,C2219)>0,"Duplicate",IF(LEFT(C2219,LEN(C2219)-1)=LEFT(OFFSET(C2219,-1,0),LEN(OFFSET(C2219,-1,0))-1),"2 Sols",""))) | C2219: =IF(A2219="","",RIGHT("00000"&IF(OR($D2219="",$E2219="",$F2219="",$G2219=""),"",IF($D2219>=$F2219,$D2219,$F2219)),5)&"-" &RIGHT("00000"&IF(OR($D2219="",$E2219="",$F2219="",$G2219=""),"",IF($D2219=$F2219,IF($E2219>=$G2219,$E2219,$G2219),IF($D2219>$F2219,$E2219,$G2219))),5)&"-" &RIGHT("00000"&IF(OR($D2219="",$E2219="",$F2219="",$G2219=""),"",IF($D2219<$F2219,$D2219,$F2219)),5)&"-" &RIGHT("00000"&IF(OR($D2219="",$E2219="",$F2219="",$G2219=""),"",IF($D2219=$F2219,IF($E2219<$G2219,$E2219,$G2219),IF($D2219<$F2219,$E2219,$G2219))),5)&"-"&O2219) | D2219: =IF($A2219="","",VALUE(MID($A2219,FIND(D$1,$A2219)+LEN(D$1),FIND(D$2,$A2219,FIND(D$1,$A2219))-(FIND(D$1,$A2219)+LEN(D$1))))) | E2219: =IF($A2219="","",VALUE(MID($A2219,FIND(E$1,$A2219)+LEN(E$1),FIND(E$2,$A2219,FIND(E$1,$A2219))-(FIND(E$1,$A2219)+LEN(E$1))))) | F2219: =IF($A2219="","",VALUE(MID($A2219,FIND(F$1,$A2219)+LEN(F$1),FIND(F$2,$A2219,FIND(F$1,$A2219))-(FIND(F$1,$A2219)+LEN(F$1))))) | G2219: =IF($A2219="","",VALUE(MID($A2219,FIND(G$1,$A2219)+LEN(G$1),FIND(G$2,$A2219,FIND(G$1,$A2219))-(FIND(G$1,$A2219)+LEN(G$1))))) | H2219: =IF($A2219="","",VALUE(MID($A2219,FIND(H$1,$A2219)+LEN(H$1),FIND(H$2,$A2219,FIND(H$1,$A2219))-(FIND(H$1,$A2219)+LEN(H$1))))) | I2219: =IF($A2219="","",VALUE(MID($A2219,FIND(I$1,$A2219)+LEN(I$1),FIND(I$2,$A2219,FIND(I$1,$A2219))-(FIND(I$1,$A2219)+LEN(I$1))))) | J2219: =IF(OR($D2219="",$E2219=""),"",$E2219^2+2*$E2219*$D2219-$D2219^2) | K2219: =IF($A2219="","",VALUE(MID($A2219,FIND(K$1,$A2219)+LEN(K$1),FIND(K$2,$A2219,FIND(K$1,$A2219))-(FIND(K$1,$A2219)+LEN(K$1))))) | L2219: =IF($A2219="","",VALUE(MID($A2219,FIND(L$1,$A2219)+LEN(L$1),FIND(L$2,$A2219,FIND(L$1,$A2219))-(FIND(L$1,$A2219)+LEN(L$1))))) | M2219: =IF(OR($F2219="",$G2219=""),"",$G2219^2+2*$G2219*$F2219-$F2219^2) | N2219: =IF(OR($H2219="",$I2219="",$J2219="",$K2219="",$L2219="",$M2219=""),"",GCD($H2219:$M2219)) | O2219: =IF($A2219="","",MID($A2219,FIND(" ",$A2219,FIND(L$1,$A2219))+1,1)) | P2219: =IF(A2219="","",TRIM(SUBSTITUTE(SUBSTITUTE(RIGHT(A2219,LEN(A2219)-FIND("=",A2219,FIND("]",A2219,FIND("]",A2219)+1))),"^2",""),".",""))) | Q2219: =IF(OR($H2219="",$L2219="",$N2219=""),"",$H2219*$L2219/$N2219) | R2219: =IF(OR($K2219="",$I2219="",$N2219=""),"",$K2219*$I2219/$N2219) | S2219: =IF(OR($O2219<>UPPER(S$2),$N2219=""),"",IF($P2219="",-1,$P2219/$N2219)) | T2219: =IF(OR($O2219<>UPPER(T$2),$N2219=""),"",IF($P2219="",-1,$P2219/$N2219)) | U2219: =IF(OR($I2219="",$L2219="",$N2219=""),"",$I2219*$L2219/$N2219) | V2219: =IF(OR($O2219<>UPPER(V$2),$N2219=""),"",IF($P2219="",-1,$P2219/$N2219)) | W2219: =IF(OR($O2219<>UPPER(W$2),$N2219=""),"",IF($P2219="",-1,$P2219/$N2219)) | X2219: =IF(OR($M2219="",$I2219="",$N2219=""),"",$M2219*$I2219/$N2219) | Y2219: =IF(OR($J2219="",$L2219="",$N2219=""),"",$J2219*$L2219/$N2219)
B2220: =IF(A2220="","",IF(COUNTIF(C$2:C2219,C2220)>0,"Duplicate",IF(LEFT(C2220,LEN(C2220)-1)=LEFT(OFFSET(C2220,-1,0),LEN(OFFSET(C2220,-1,0))-1),"2 Sols",""))) | C2220: =IF(A2220="","",RIGHT("00000"&IF(OR($D2220="",$E2220="",$F2220="",$G2220=""),"",IF($D2220>=$F2220,$D2220,$F2220)),5)&"-" &RIGHT("00000"&IF(OR($D2220="",$E2220="",$F2220="",$G2220=""),"",IF($D2220=$F2220,IF($E2220>=$G2220,$E2220,$G2220),IF($D2220>$F2220,$E2220,$G2220))),5)&"-" &RIGHT("00000"&IF(OR($D2220="",$E2220="",$F2220="",$G2220=""),"",IF($D2220<$F2220,$D2220,$F2220)),5)&"-" &RIGHT("00000"&IF(OR($D2220="",$E2220="",$F2220="",$G2220=""),"",IF($D2220=$F2220,IF($E2220<$G2220,$E2220,$G2220),IF($D2220<$F2220,$E2220,$G2220))),5)&"-"&O2220) | D2220: =IF($A2220="","",VALUE(MID($A2220,FIND(D$1,$A2220)+LEN(D$1),FIND(D$2,$A2220,FIND(D$1,$A2220))-(FIND(D$1,$A2220)+LEN(D$1))))) | E2220: =IF($A2220="","",VALUE(MID($A2220,FIND(E$1,$A2220)+LEN(E$1),FIND(E$2,$A2220,FIND(E$1,$A2220))-(FIND(E$1,$A2220)+LEN(E$1))))) | F2220: =IF($A2220="","",VALUE(MID($A2220,FIND(F$1,$A2220)+LEN(F$1),FIND(F$2,$A2220,FIND(F$1,$A2220))-(FIND(F$1,$A2220)+LEN(F$1))))) | G2220: =IF($A2220="","",VALUE(MID($A2220,FIND(G$1,$A2220)+LEN(G$1),FIND(G$2,$A2220,FIND(G$1,$A2220))-(FIND(G$1,$A2220)+LEN(G$1))))) | H2220: =IF($A2220="","",VALUE(MID($A2220,FIND(H$1,$A2220)+LEN(H$1),FIND(H$2,$A2220,FIND(H$1,$A2220))-(FIND(H$1,$A2220)+LEN(H$1))))) | I2220: =IF($A2220="","",VALUE(MID($A2220,FIND(I$1,$A2220)+LEN(I$1),FIND(I$2,$A2220,FIND(I$1,$A2220))-(FIND(I$1,$A2220)+LEN(I$1))))) | J2220: =IF(OR($D2220="",$E2220=""),"",$E2220^2+2*$E2220*$D2220-$D2220^2) | K2220: =IF($A2220="","",VALUE(MID($A2220,FIND(K$1,$A2220)+LEN(K$1),FIND(K$2,$A2220,FIND(K$1,$A2220))-(FIND(K$1,$A2220)+LEN(K$1))))) | L2220: =IF($A2220="","",VALUE(MID($A2220,FIND(L$1,$A2220)+LEN(L$1),FIND(L$2,$A2220,FIND(L$1,$A2220))-(FIND(L$1,$A2220)+LEN(L$1))))) | M2220: =IF(OR($F2220="",$G2220=""),"",$G2220^2+2*$G2220*$F2220-$F2220^2) | N2220: =IF(OR($H2220="",$I2220="",$J2220="",$K2220="",$L2220="",$M2220=""),"",GCD($H2220:$M2220)) | O2220: =IF($A2220="","",MID($A2220,FIND(" ",$A2220,FIND(L$1,$A2220))+1,1)) | P2220: =IF(A2220="","",TRIM(SUBSTITUTE(SUBSTITUTE(RIGHT(A2220,LEN(A2220)-FIND("=",A2220,FIND("]",A2220,FIND("]",A2220)+1))),"^2",""),".",""))) | Q2220: =IF(OR($H2220="",$L2220="",$N2220=""),"",$H2220*$L2220/$N2220) | R2220: =IF(OR($K2220="",$I2220="",$N2220=""),"",$K2220*$I2220/$N2220) | S2220: =IF(OR($O2220<>UPPER(S$2),$N2220=""),"",IF($P2220="",-1,$P2220/$N2220)) | T2220: =IF(OR($O2220<>UPPER(T$2),$N2220=""),"",IF($P2220="",-1,$P2220/$N2220)) | U2220: =IF(OR($I2220="",$L2220="",$N2220=""),"",$I2220*$L2220/$N2220) | V2220: =IF(OR($O2220<>UPPER(V$2),$N2220=""),"",IF($P2220="",-1,$P2220/$N2220)) | W2220: =IF(OR($O2220<>UPPER(W$2),$N2220=""),"",IF($P2220="",-1,$P2220/$N2220)) | X2220: =IF(OR($M2220="",$I2220="",$N2220=""),"",$M2220*$I2220/$N2220) | Y2220: =IF(OR($J2220="",$L2220="",$N2220=""),"",$J2220*$L2220/$N2220)
B2221: =IF(A2221="","",IF(COUNTIF(C$2:C2220,C2221)>0,"Duplicate",IF(LEFT(C2221,LEN(C2221)-1)=LEFT(OFFSET(C2221,-1,0),LEN(OFFSET(C2221,-1,0))-1),"2 Sols",""))) | C2221: =IF(A2221="","",RIGHT("00000"&IF(OR($D2221="",$E2221="",$F2221="",$G2221=""),"",IF($D2221>=$F2221,$D2221,$F2221)),5)&"-" &RIGHT("00000"&IF(OR($D2221="",$E2221="",$F2221="",$G2221=""),"",IF($D2221=$F2221,IF($E2221>=$G2221,$E2221,$G2221),IF($D2221>$F2221,$E2221,$G2221))),5)&"-" &RIGHT("00000"&IF(OR($D2221="",$E2221="",$F2221="",$G2221=""),"",IF($D2221<$F2221,$D2221,$F2221)),5)&"-" &RIGHT("00000"&IF(OR($D2221="",$E2221="",$F2221="",$G2221=""),"",IF($D2221=$F2221,IF($E2221<$G2221,$E2221,$G2221),IF($D2221<$F2221,$E2221,$G2221))),5)&"-"&O2221) | D2221: =IF($A2221="","",VALUE(MID($A2221,FIND(D$1,$A2221)+LEN(D$1),FIND(D$2,$A2221,FIND(D$1,$A2221))-(FIND(D$1,$A2221)+LEN(D$1))))) | E2221: =IF($A2221="","",VALUE(MID($A2221,FIND(E$1,$A2221)+LEN(E$1),FIND(E$2,$A2221,FIND(E$1,$A2221))-(FIND(E$1,$A2221)+LEN(E$1))))) | F2221: =IF($A2221="","",VALUE(MID($A2221,FIND(F$1,$A2221)+LEN(F$1),FIND(F$2,$A2221,FIND(F$1,$A2221))-(FIND(F$1,$A2221)+LEN(F$1))))) | G2221: =IF($A2221="","",VALUE(MID($A2221,FIND(G$1,$A2221)+LEN(G$1),FIND(G$2,$A2221,FIND(G$1,$A2221))-(FIND(G$1,$A2221)+LEN(G$1))))) | H2221: =IF($A2221="","",VALUE(MID($A2221,FIND(H$1,$A2221)+LEN(H$1),FIND(H$2,$A2221,FIND(H$1,$A2221))-(FIND(H$1,$A2221)+LEN(H$1))))) | I2221: =IF($A2221="","",VALUE(MID($A2221,FIND(I$1,$A2221)+LEN(I$1),FIND(I$2,$A2221,FIND(I$1,$A2221))-(FIND(I$1,$A2221)+LEN(I$1))))) | J2221: =IF(OR($D2221="",$E2221=""),"",$E2221^2+2*$E2221*$D2221-$D2221^2) | K2221: =IF($A2221="","",VALUE(MID($A2221,FIND(K$1,$A2221)+LEN(K$1),FIND(K$2,$A2221,FIND(K$1,$A2221))-(FIND(K$1,$A2221)+LEN(K$1))))) | L2221: =IF($A2221="","",VALUE(MID($A2221,FIND(L$1,$A2221)+LEN(L$1),FIND(L$2,$A2221,FIND(L$1,$A2221))-(FIND(L$1,$A2221)+LEN(L$1))))) | M2221: =IF(OR($F2221="",$G2221=""),"",$G2221^2+2*$G2221*$F2221-$F2221^2) | N2221: =IF(OR($H2221="",$I2221="",$J2221="",$K2221="",$L2221="",$M2221=""),"",GCD($H2221:$M2221)) | O2221: =IF($A2221="","",MID($A2221,FIND(" ",$A2221,FIND(L$1,$A2221))+1,1)) | P2221: =IF(A2221="","",TRIM(SUBSTITUTE(SUBSTITUTE(RIGHT(A2221,LEN(A2221)-FIND("=",A2221,FIND("]",A2221,FIND("]",A2221)+1))),"^2",""),".",""))) | Q2221: =IF(OR($H2221="",$L2221="",$N2221=""),"",$H2221*$L2221/$N2221) | R2221: =IF(OR($K2221="",$I2221="",$N2221=""),"",$K2221*$I2221/$N2221) | S2221: =IF(OR($O2221<>UPPER(S$2),$N2221=""),"",IF($P2221="",-1,$P2221/$N2221)) | T2221: =IF(OR($O2221<>UPPER(T$2),$N2221=""),"",IF($P2221="",-1,$P2221/$N2221)) | U2221: =IF(OR($I2221="",$L2221="",$N2221=""),"",$I2221*$L2221/$N2221) | V2221: =IF(OR($O2221<>UPPER(V$2),$N2221=""),"",IF($P2221="",-1,$P2221/$N2221)) | W2221: =IF(OR($O2221<>UPPER(W$2),$N2221=""),"",IF($P2221="",-1,$P2221/$N2221)) | X2221: =IF(OR($M2221="",$I2221="",$N2221=""),"",$M2221*$I2221/$N2221) | Y2221: =IF(OR($J2221="",$L2221="",$N2221=""),"",$J2221*$L2221/$N2221)
